Workbook

Sheet Как пользоваться
A1: Реестр источников событий — Кембридж и окрестности (v0.3, сентябрь 2026)
A3: Источники — основная таблица. Одна строка = один источник. Фильтры в заголовке.
A4: Жёлтым выделено: URL не проверен или не указан — нужно найти/подтвердить перед написанием парсера.
A5: «URL проверен = да» — адрес подтверждён поиском; «проверить» — источник известен, но адрес и формат нужно сверить.
A6: Приоритет: 1 — брать в MVP, 2 — вторая волна, 3 — когда будет время.
A7: Способ сбора: RSS / iCal / API — дешёвый и надёжный; HTML — парсинг; Ручной — ежегодные события, проще завести руками.
A8: Сводка — счётчики по категориям (формулы, пересчитываются сами).
A9: Схема события — поля, которые парсер должен заполнять для каждого события.
A10: Категории и теги — справочник значений для полей category и тегов.
A12: Пример строки: S047 Talks.cam — готовые iCal/RSS/XML-фиды с датой, местом и организатором; приоритет 1.

Sheet Источники
A1: ID | B1: Категория | C1: Источник | D1: Тип источника | E1: URL | F1: Что покрывает | G1: Зона | H1: Способ сбора | I1: Частота | J1: Приоритет | K1: URL проверен | L1: Заметки
A2: S001 | B2: Сквозные агрегаторы | C2: Visit Cambridge — events | D2: Агрегатор | E2: https://www.visitcambridge.org | F2: Официальный туристический календарь, все категории | G2: Центр | H2: HTML (уточнить фид) | I2: Ежедневно | J2: 1 | K2: да | L2: Хорошая опорная база, но туристический уклон
A3: S002 | B3: Сквозные агрегаторы | C3: What's On In Cambridge | D3: Агрегатор | E3: https://www.whatsonincambridge.com/events/ | F3: Календарь событий, все категории | G3: Центр | H3: HTML | I3: Ежедневно | J3: 1 | K3: да | L3: Сами предупреждают, что обновляют не каждый день — использовать как подсказку, сверять с первоисточником
A4: S003 | B4: Сквозные агрегаторы | C4: Cambridge Independent — What's On | D4: СМИ | E4: https://www.cambridgeindependent.co.uk/whats-on/ | F4: Анонсы концертов, театра, кино, семейного | G4: Центр + 30 мин | H4: HTML / RSS (уточнить) | I4: Ежедневно | J4: 1 | K4: да | L4: Также спортивный раздел — календари United
A5: S004 | B5: Сквозные агрегаторы | C5: Cambridge News / CambridgeshireLive | D5: СМИ | E5: https://www.cambridge-news.co.uk | F5: Новости, анонсы, отмены, перекрытия | G5: Центр + час | H5: RSS (уточнить) | I5: 2–3 раза в день | J5: 1 | K5: да | L5: Ключевой источник для контура отмен
A6: S005 | B6: Сквозные агрегаторы | C6: Cambridge 105 — события | D6: СМИ / календарь | E6: https://cambridge105.co.uk | F6: Общественное радио, календарь местных событий | G6: Центр | H6: HTML | I6: Ежедневно | J6: 1 | K6: да | L6: Поймал Thriplow Daffodil Weekend — сильный источник по деревенскому long tail
A7: S006 | B7: Сквозные агрегаторы | C7: Ents24 — Cambridge | D7: Агрегатор | E7: https://www.ents24.com/whatson/cambridge | F7: Концерты, комедия, театр по всем площадкам | G7: Центр + 30 мин | H7: HTML | I7: Ежедневно | J7: 1 | K7: да | L7: Удобно ловить объявления новых шоу
A8: S007 | B8: Сквозные агрегаторы | C8: Skiddle — Cambridge | D8: Агрегатор / билеты | E8: https://www.skiddle.com/whats-on/Cambridge/ | F8: Клубы, гиги, фестивали | G8: Центр | H8: API (партнёрская программа) | I8: Ежедневно | J8: 1 | K8: да | L8: Есть API и партнёрка — сразу и данные, и монетизация
A9: S008 | B9: Сквозные агрегаторы | C9: Eventbrite — Cambridge | D9: Агрегатор / билеты | E9: https://www.eventbrite.co.uk | F9: Воркшопы, лекции, нетворкинг, благотворительность | G9: Центр + 30 мин | H9: HTML (публичный поиск по API закрыт — проверить) | I9: Ежедневно | J9: 2 | K9: проверить | L9: Много шума — нужен жёсткий фильтр
A10: S009 | B10: Сквозные агрегаторы | C10: Songkick — площадки Кембриджа | D10: Агрегатор | E10: https://www.songkick.com | F10: Концерты по площадкам | G10: Центр | H10: HTML (API для новых партнёров ограничен — проверить) | I10: Еженедельно | J10: 3 | K10: да
A11: S010 | B11: Сквозные агрегаторы | C11: Peterborough Telegraph | D11: СМИ | E11: https://www.peterboroughtoday.co.uk | F11: Север графства: Уиттлси, Питерборо, фены | G11: Час | H11: RSS (уточнить) | I11: Ежедневно | J11: 2 | K11: да | L11: Закрывает дыру по Straw Bear и северу
A12: S011 | B12: Концерты | C12: Cambridge Corn Exchange | D12: Площадка | E12: https://cambridgelive.org.uk | F12: Крупные концерты, комедия, балет, городские события | G12: Центр | H12: HTML | I12: Ежедневно | J12: 1 | K12: да | L12: Сайт Cambridge Live — там же городские события (фейерверки и др.)
A13: S012 | B13: Концерты | C13: Cambridge Junction | D13: Площадка | E13: https://www.junction.co.uk | F13: Концерты, комедия, клубные вечера, театр | G13: Центр | H13: HTML | I13: Ежедневно | J13: 1 | K13: проверить
A14: S013 | B14: Концерты | C14: The Portland Arms | D14: Площадка | F14: Небольшие рок/инди-концерты | G14: Центр | H14: Через Ents24/Skiddle | I14: Еженедельно | J14: 2 | K14: проверить | L14: Собственный сайт найти
A15: S014 | B15: Концерты | C15: Storey's Field Centre (Eddington) | D15: Площадка | F15: Камерная музыка, фолк, джаз | G15: Центр | H15: HTML | I15: Еженедельно | J15: 2 | K15: проверить
A16: S015 | B16: Концерты | C16: West Road Concert Hall | D16: Площадка | F16: Классика, университетские оркестры | G16: Центр | H16: HTML | I16: Еженедельно | J16: 2 | K16: проверить
A17: S016 | B17: Концерты | C17: Хоровая музыка колледжей (King's, St John's, Trinity) | D17: Площадка | F17: Evensong, концерты хоров, органные вечера | G17: Центр | H17: HTML по колледжам | I17: Еженедельно | J17: 3 | K17: проверить | L17: Бесплатно — хороший материал для рубрики «бесплатно»
A18: S017 | B18: Концерты | C18: Saffron Hall | D18: Площадка | F18: Классика и крупные концерты | G18: Час | H18: HTML | I18: Еженедельно | J18: 2 | K18: проверить | L18: Saffron Walden
A19: S018 | B19: Спорт — смотреть | C19: Cambridge United | D19: Клуб | E19: https://www.cambridgeunited.com | F19: Матчи Лиги 1, кубки | G19: Центр | H19: Синхронизация календаря (клуб её предлагает) / HTML | I19: Еженедельно | J19: 1 | K19: да | L19: Календарь сезона публикуется летом целиком
A20: S019 | B20: Спорт — смотреть | C20: Cambridge City FC | D20: Клуб | F20: Нон-лиг футбол | G20: 30 мин | H20: HTML | I20: Еженедельно | J20: 3 | K20: проверить
A21: S020 | B21: Спорт — смотреть | C21: Cambridge Rugby Club | D21: Клуб | F21: Регби, National League | G21: Центр | H21: HTML | I21: Еженедельно | J21: 2 | K21: проверить
A22: S021 | B22: Спорт — смотреть | C22: Newmarket Racecourses | D22: Площадка | F22: Скачки, летние концерты Newmarket Nights | G22: 30 мин | H22: HTML | I22: Еженедельно | J22: 1 | K22: проверить | L22: Сайт Jockey Club
A23: S022 | B23: Спорт — смотреть | C23: Huntingdon Racecourse | D23: Площадка | F23: Скачки | G23: 30 мин | H23: HTML | I23: Еженедельно | J23: 3 | K23: проверить | L23: Сайт Jockey Club
A24: S023 | B24: Спорт — смотреть | C24: CUCBC — May Bumps / Lent Bumps | D24: Организатор | F24: Университетские гонки гребных лодок: Lent Bumps (февраль–март) и May Bumps (июнь) | G24: Центр | H24: HTML | I24: Сезонно | J24: 2 | K24: проверить
A25: S024 | B25: Спорт — смотреть | C25: Town Bumps (Cambridgeshire Rowing Association) | D25: Организатор | F25: Городские гонки гребных лодок, лето | G25: Центр | H25: HTML | I25: Сезонно | J25: 3 | K25: проверить
A26: S025 | B26: Спорт — смотреть | C26: Varsity-матчи (Oxford vs Cambridge) | D26: Организатор | F26: Регби, гребля и др. дерби университетов | G26: Центр + Лондон | H26: Ручной (календарь) | I26: Ежегодно | J26: 3 | K26: проверить
A27: S026 | B27: Спорт — участвовать | C27: Chariots of Fire | D27: Организатор | E27: https://www.hcrlaw.com | F27: Благотворительная эстафета, сентябрь | G27: Центр | H27: Ручной (ежегодно) + RunThrough | I27: Ежегодно | J27: 1 | K27: да | L27: Регистрация через RunThrough
A28: S027 | B28: Спорт — участвовать | C28: RunThrough — события в Кембридже | D28: Организатор / регистрация | E28: https://www.runthrough.co.uk | F28: Забеги, эстафеты | G28: Центр + 30 мин | H28: HTML | I28: Еженедельно | J28: 2 | K28: да
A29: S028 | B29: Спорт — участвовать | C29: Cambridge Half Marathon | D29: Организатор | F29: Полумарафон, март | G29: Центр | H29: Ручной (ежегодно) | I29: Ежегодно | J29: 1 | K29: проверить | L29: Важен и для рубрики «Практическое» — перекрытия
A30: S029 | B30: Спорт — участвовать | C30: Let's Do This — Cambridgeshire | D30: Агрегатор / регистрация | E30: https://www.letsdothis.com | F30: Забеги, триатлоны, велозаезды | G30: Час | H30: HTML | I30: Еженедельно | J30: 2 | K30: да
A31: S030 | B31: Фестивали | C31: Cambridge Festival (университет) | D31: Организатор | F31: Наука, гуманитарные темы, весна | G31: Центр | H31: HTML + talks.cam | I31: Сезонно | J31: 1 | K31: проверить
A32: S031 | B32: Фестивали | C32: Cambridge Folk Festival | D32: Организатор | F32: Фолк-фестиваль, лето | G32: Центр | H32: Ручной (ежегодно) | I32: Ежегодно | J32: 1 | K32: проверить
A33: S032 | B33: Фестивали | C33: Cambridge Beer Festival | D33: Организатор | E33: https://www.cambridgebeerfestival.com | F33: Пивной фестиваль CAMRA, май | G33: Центр | H33: Ручной (ежегодно) | I33: Ежегодно | J33: 1 | K33: да
A34: S033 | B34: Фестивали | C34: Strawberry Fair | D34: Организатор | F34: Бесплатный фестиваль на Midsummer Common, июнь | G34: Центр | H34: Ручной + соцсети | I34: Ежегодно | J34: 1 | K34: проверить | L34: Бывали отмены — мониторить
A35: S034 | B35: Фестивали | C35: Whittlesea Straw Bear Festival | D35: Организатор | F35: Средневековый зимний фестиваль, январь | G35: Час | H35: Ручной + Peterborough Telegraph | I35: Ежегодно | J35: 2 | K35: проверить
A36: S035 | B36: Фестивали | C36: Cambridge Film Festival | D36: Организатор | F36: Кинофестиваль, осень | G36: Центр | H36: Ручной (ежегодно) | I36: Ежегодно | J36: 2 | K36: проверить
A37: S036 | B37: Фестивали | C37: Cambridge Literary Festival | D37: Организатор | F37: Литфестиваль, весна и осень | G37: Центр | H37: HTML | I37: Сезонно | J37: 2 | K37: проверить
A38: S037 | B38: Фестивали | C38: Cambridge Science Festival / семейные программы | D38: Организатор | F38: См. Cambridge Festival | G38: Центр | H38: — | I38: — | J38: 3 | K38: проверить | L38: Дубль — проверить, не слит ли с Cambridge Festival
A39: S038 | B39: Ярмарки | C39: Mill Road Winter Fair | D39: Организатор | E39: https://www.millroadwinterfair.org | F39: Уличная ярмарка, первая суббота декабря; Mill Road Fringe в течение года | G39: Центр | H39: HTML + соцсети | I39: Еженедельно в сезон | J39: 1 | K39: да | L39: Отмены публикуются в соцсетях — нужен контур отмен
A40: S039 | B40: Ярмарки | C40: Рождественские маркеты в центре | D40: Организатор | F40: Сезонные рынки | G40: Центр | H40: Ручной + городской совет | I40: Сезонно | J40: 1 | K40: проверить
...

Sheet Сводка
A1: Категория | B1: Всего источников | C1: Приоритет 1 | D1: URL проверен | E1: Осталось проверить
A2: Сквозные агрегаторы | B2: =COUNTIF(Источники!$B$2:$B$90,A2) -> 10 | C2: =COUNTIFS(Источники!$B$2:$B$90,A2,Источники!$J$2:$J$90,1) -> 7 | D2: =COUNTIFS(Источники!$B$2:$B$90,A2,Источники!$K$2:$K$90,"да") -> 9 | E2: =B2-D2 -> 1
A3: Концерты | B3: =COUNTIF(Источники!$B$2:$B$90,A3) -> 7 | C3: =COUNTIFS(Источники!$B$2:$B$90,A3,Источники!$J$2:$J$90,1) -> 2 | D3: =COUNTIFS(Источники!$B$2:$B$90,A3,Источники!$K$2:$K$90,"да") -> 1 | E3: =B3-D3 -> 6
A4: Спорт — смотреть | B4: =COUNTIF(Источники!$B$2:$B$90,A4) -> 11 | C4: =COUNTIFS(Источники!$B$2:$B$90,A4,Источники!$J$2:$J$90,1) -> 3 | D4: =COUNTIFS(Источники!$B$2:$B$90,A4,Источники!$K$2:$K$90,"да") -> 2 | E4: =B4-D4 -> 9
A5: Спорт — участвовать | B5: =COUNTIF(Источники!$B$2:$B$90,A5) -> 6 | C5: =COUNTIFS(Источники!$B$2:$B$90,A5,Источники!$J$2:$J$90,1) -> 3 | D5: =COUNTIFS(Источники!$B$2:$B$90,A5,Источники!$K$2:$K$90,"да") -> 3 | E5: =B5-D5 -> 3
A6: Фестивали | B6: =COUNTIF(Источники!$B$2:$B$90,A6) -> 10 | C6: =COUNTIFS(Источники!$B$2:$B$90,A6,Источники!$J$2:$J$90,1) -> 5 | D6: =COUNTIFS(Источники!$B$2:$B$90,A6,Источники!$K$2:$K$90,"да") -> 2 | E6: =B6-D6 -> 8
A7: Ярмарки | B7: =COUNTIF(Источники!$B$2:$B$90,A7) -> 3 | C7: =COUNTIFS(Источники!$B$2:$B$90,A7,Источники!$J$2:$J$90,1) -> 2 | D7: =COUNTIFS(Источники!$B$2:$B$90,A7,Источники!$K$2:$K$90,"да") -> 1 | E7: =B7-D7 -> 2
A8: Театр | B8: =COUNTIF(Источники!$B$2:$B$90,A8) -> 4 | C8: =COUNTIFS(Источники!$B$2:$B$90,A8,Источники!$J$2:$J$90,1) -> 2 | D8: =COUNTIFS(Источники!$B$2:$B$90,A8,Источники!$K$2:$K$90,"да") -> 0 | E8: =B8-D8 -> 4
A9: Кино | B9: =COUNTIF(Источники!$B$2:$B$90,A9) -> 2 | C9: =COUNTIFS(Источники!$B$2:$B$90,A9,Источники!$J$2:$J$90,1) -> 1 | D9: =COUNTIFS(Источники!$B$2:$B$90,A9,Источники!$K$2:$K$90,"да") -> 0 | E9: =B9-D9 -> 2
A10: Лекции | B10: =COUNTIF(Источники!$B$2:$B$90,A10) -> 3 | C10: =COUNTIFS(Источники!$B$2:$B$90,A10,Источники!$J$2:$J$90,1) -> 2 | D10: =COUNTIFS(Источники!$B$2:$B$90,A10,Источники!$K$2:$K$90,"да") -> 2 | E10: =B10-D10 -> 1
A11: Выставки и музеи | B11: =COUNTIF(Источники!$B$2:$B$90,A11) -> 4 | C11: =COUNTIFS(Источники!$B$2:$B$90,A11,Источники!$J$2:$J$90,1) -> 3 | D11: =COUNTIFS(Источники!$B$2:$B$90,A11,Источники!$K$2:$K$90,"да") -> 0 | E11: =B11-D11 -> 4
A12: Детям и семьям | B12: =COUNTIF(Источники!$B$2:$B$90,A12) -> 3 | C12: =COUNTIFS(Источники!$B$2:$B$90,A12,Источники!$J$2:$J$90,1) -> 1 | D12: =COUNTIFS(Источники!$B$2:$B$90,A12,Источники!$K$2:$K$90,"да") -> 0 | E12: =B12-D12 -> 3
A13: Еда и напитки | B13: =COUNTIF(Источники!$B$2:$B$90,A13) -> 3 | C13: =COUNTIFS(Источники!$B$2:$B$90,A13,Источники!$J$2:$J$90,1) -> 1 | D13: =COUNTIFS(Источники!$B$2:$B$90,A13,Источники!$K$2:$K$90,"да") -> 1 | E13: =B13-D13 -> 2
... A22: Практическое | B22: =COUNTIF(Источники!$B$2:$B$90,A22) -> 3 | C22: =COUNTIFS(Источники!$B$2:$B$90,A22,Источники!$J$2:$J$90,1) -> 0 | D22: =COUNTIFS(Источники!$B$2:$B$90,A22,Источники!$K$2:$K$90,"да") -> 0 | E22: =B22-D22 -> 3
A23: Итого | B23: =SUM(B2:B22) -> 89 | C23: =SUM(C2:C22) -> 37 | D23: =SUM(D2:D22) -> 24 | E23: =SUM(E2:E22) -> 65

Sheet Схема события
A1: Поле | B1: Тип | C1: Обязательное | D1: Пример | E1: Комментарий
A2: event_id | B2: текст | C2: да | D2: EV-2026-000123 | E2: Внутренний ID
A3: title | B3: текст | C3: да | D3: Cambridge United vs AFC Wimbledon
A4: category | B4: список | C4: да | D4: Спорт — смотреть | E4: Из листа «Категории и теги»
A5: date_start | B5: дата | C5: да | D5: 2026-09-26
A6: time_start | B6: время | C6: да, если известно | D6: 15:00 | E6: Пусто = весь день
A7: date_end | B7: дата | C7: нет | D7: 2026-09-26 | E7: Для многодневных
A8: time_end | B8: время | C8: нет | D8: 17:00
A9: venue_name | B9: текст | C9: да | D9: Abbey Stadium
A10: address | B10: текст | C10: да | D10: Newmarket Road, Cambridge | E10: Точный адрес
A11: postcode | B11: текст | C11: да | D11: (заполнять из источника) | E11: Для карты и расчёта зоны
A12: lat / lon | B12: число | C12: нет | D12: 52.21, 0.15 | E12: Геокодирование по postcode
A13: zone | B13: список | C13: да | D13: Центр | E13: Тег: Центр / до 30 мин / до часа — считается автоматически
A14: price_from | B14: число, £ | C14: нет | D14: 0 | E14: 0 = бесплатно
A15: price_tag | B15: список | C15: да | D15: бесплатно / до £10 / дороже
A16: audience | B16: список (несколько) | C16: нет | D16: дети 5–12; семьи
A17: booking | B17: список | C17: да | D17: без билетов / бронировать / продажа скоро
A18: status | B18: список | C18: да | D18: по плану | E18: по плану / перенесено / отменено / sold out
A19: ticket_url | B19: URL | C19: нет | E19: Здесь партнёрская ссылка, если есть
A20: source_id | B20: ссылка | C20: да | D20: S018 | E20: ID из листа «Источники»
A21: source_url | B21: URL | C21: да | E21: Страница события у первоисточника
A22: description_short | B22: текст | C22: да | E22: 2–3 предложения своими словами (не копировать)
A23: score | B23: число 1–10 | C23: нет | D23: 8 | E23: Оценка LLM «стоит ли внимания»
A24: last_checked | B24: дата-время | C24: да | E24: Когда контур отмен последний раз проверял

Sheet Категории и теги
A1: Ось | B1: Значение
A2: Категория | B2: Концерты
A3: Категория | B3: Спорт — смотреть
A4: Категория | B4: Спорт — участвовать
A5: Категория | B5: Фестивали
A6: Категория | B6: Ярмарки
A7: Категория | B7: Театр
A8: Категория | B8: Кино
A9: Категория | B9: Лекции
A10: Категория | B10: Выставки и музеи
A11: Категория | B11: Детям и семьям
A12: Категория | B12: Еда и напитки
... A39: Статус | B39: sold out
