Workbook

Sheet Как пользоваться
A1: Реестр источников событий — Кембридж и окрестности (v0.4, сентябрь 2026)
A3: Источники — основная таблица. Одна строка = один источник. Фильтры в заголовке.
A4: Жёлтым выделено: URL не проверен или не указан — нужно найти/подтвердить перед написанием парсера.
A5: «URL проверен = да» — адрес подтверждён поиском; «проверить» — источник известен, но адрес и формат нужно сверить.
A6: Приоритет: 1 — брать в MVP, 2 — вторая волна, 3 — когда будет время.
A7: Способ сбора: RSS / iCal / API — дешёвый и надёжный; HTML — парсинг; Ручной — ежегодные события, проще завести руками.
A8: Сводка — счётчики по категориям (формулы, пересчитываются сами).
A9: Схема события — поля, которые парсер должен заполнять для каждого события.
A10: Категории и теги — справочник значений для полей category и тегов.
A12: Пример строки: S047 Talks.cam — готовые iCal/RSS/XML-фиды с датой, местом и организатором; приоритет 1.
A13: v0.4 (2026-09-27): проверены источники приоритета 1 — см. лист «Проверка P1»; новые столбцы «Endpoint для сбора», «robots.txt», «Проверено». «URL проверен = нет» — URL не отвечает (красный).
A14: v0.4, правки после этапа 1: Eventbrite (S008) поднят до приоритета 1; добавлены S090 DesignMyNight и S091 Cambridge Live Tickets; лист «Контрольные события» (источник — data/control_events.json).
... A20: v0.10 (2026-09-30): этап 7c — Cambridge Union: Varsity (S176) и termcard на Issuu (S177); ссылки S123 и S144 исправлены по проверкам выпуска.

Sheet Источники
A1: ID | B1: Категория | C1: Источник | D1: Тип источника | E1: URL | F1: Что покрывает | G1: Зона | H1: Способ сбора | I1: Частота | J1: Приоритет | K1: URL проверен | L1: Заметки | M1: Endpoint для сбора | N1: robots.txt | O1: Проверено | P1: Партнёрская программа
A2: S001 | B2: Сквозные агрегаторы | C2: Visit Cambridge — events | D2: Агрегатор | E2: https://www.visitcambridge.org | F2: Официальный туристический календарь, все категории | G2: Центр | H2: API + HTML | I2: Ежедневно | J2: 1 | K2: да | L2: Хорошая опорная база, но туристический уклон. v0.4: внутренний API vc-map отдаёт события с адресом и postcode, но без дат — даты брать со страниц /event/… Этап 6: подключён — 7 разделов /event-categories/ (постранично) + страницы событий; раздел family-friendly → категория family | M2: https://www.visitcambridge.org/wp-json/vc-map/v1/events | N2: разрешено | O2: 2026-09-28 | P2: события ведут к: продавец не определён — 17 соб.; Ticket Tailor — 6 соб.: программы нет; DigiTickets — 3 соб.: программа есть
A3: S002 | B3: Сквозные агрегаторы | C3: What's On In Cambridge | D3: Агрегатор | E3: https://www.whatsonincambridge.com/__superjs/challenge?u=%2Fevents%2F | F3: Календарь событий, все категории | G3: Центр | H3: RSS | I3: Ежедневно | J3: 1 | K3: да | L3: Сами предупреждают, что обновляют не каждый день — использовать как подсказку, сверять с первоисточником. v0.4: RSS жив (10 записей); страница /events/ за JS-проверкой | M3: https://www.whatsonincambridge.com/feed/ | N3: разрешено | O3: 2026-09-27
A4: S003 | B4: Сквозные агрегаторы | C4: Cambridge Independent — What's On | D4: СМИ | E4: https://www.cambridgeindependent.co.uk/whats-on/ | F4: Анонсы концертов, театра, кино, семейного | G4: Центр + 30 мин | H4: RSS | I4: Ежедневно | J4: 1 | K4: да | L4: Также спортивный раздел — календари United | M4: https://www.cambridgeindependent.co.uk/_api/rss/cambridge_independent_whatson_feed.xml | N4: разрешено | O4: 2026-09-27 | P4: события ведут к: продавец не определён — 5 соб.; Cambridge Live (касса Corn Exchange и Guildhall) — 2 соб.: программы нет; WeGotTickets — 2 соб.: программа есть
A5: S004 | B5: Сквозные агрегаторы | C5: Cambridge News / CambridgeshireLive | D5: СМИ | E5: https://www.cambridge-news.co.uk | F5: Новости, анонсы, отмены, перекрытия | G5: Центр + час | H5: RSS | I5: 2–3 раза в день | J5: 1 | K5: да | L5: Ключевой источник для контура отмен. v0.4: раздел What's On: /whats-on/?service=rss; общий фид новостей /?service=rss — для контура отмен | M5: https://www.cambridge-news.co.uk/whats-on/?service=rss | N5: разрешено | O5: 2026-09-27 | P5: события ведут к: продавец не определён — 2 соб.
A6: S005 | B6: Сквозные агрегаторы | C6: Cambridge 105 — события | D6: СМИ / календарь | E6: https://cambridge105.co.uk | F6: Общественное радио, календарь местных событий | G6: Центр | H6: iCal | I6: Ежедневно | J6: 1 | K6: да | L6: Поймал Thriplow Daffodil Weekend — сильный источник по деревенскому long tail. v0.4: iCal The Events Calendar (22 события) + REST /wp-json/tribe/events/v1/events | M6: https://cambridge105.co.uk/whatson/?ical=1 | N6: разрешено | O6: 2026-09-27 | P6: события ведут к: продавец не определён — 10 соб.; Spektrix (касса площадки) — 1 соб.: программы нет; Cambridge Live (касса Corn Exchange и Guildhall) — 1 соб.: программы нет
A7: S006 | B7: Сквозные агрегаторы | C7: Ents24 — Cambridge | D7: Агрегатор | E7: https://www.ents24.com/whatson/cambridge | F7: Концерты, комедия, театр по всем площадкам | G7: Центр + 30 мин | H7: JSON-LD | I7: Ежедневно | J7: 1 | K7: да | L7: Удобно ловить объявления новых шоу. v0.4: JSON-LD на первой странице списка (~37 событий), продолжение подгружается JS; через Ents24 ловим и Arts Theatre (S041) | M7: https://www.ents24.com/whatson/cambridge | N7: разрешено | O7: 2026-09-27 | P7: события ведут к: Cambridge Live (касса Corn Exchange и Guildhall) — 1 соб.: программы нет
A8: S007 | B8: Сквозные агрегаторы | C8: Skiddle — Cambridge | D8: Агрегатор / билеты | E8: https://www.skiddle.com/whats-on/Cambridge/ | F8: Клубы, гиги, фестивали | G8: Центр | H8: JSON-LD | I8: Ежедневно | J8: 1 | K8: да | L8: Есть API и партнёрка — сразу и данные, и монетизация. v0.4: ~49 событий JSON-LD на первой странице списка; продолжение подгружается JS; API и ключ не нужны (решение после этапа 1) | M8: https://www.skiddle.com/whats-on/Cambridge/ | N8: разрешено | O8: 2026-09-27 | P8: Skiddle: есть — Skiddle Ticket Affiliate Programme (своя)
A9: S008 | B9: Сквозные агрегаторы | C9: Eventbrite — Cambridge | D9: Агрегатор / билеты | E9: https://www.eventbrite.co.uk/d/united-kingdom--cambridge/all-events/ | F9: Воркшопы, лекции, нетворкинг, благотворительность | G9: Центр + 30 мин | H9: JSON-LD | I9: Ежедневно | J9: 1 | K9: да | L9: Много шума — нужен жёсткий фильтр. v0.4: поднят до P1 в v0.4; 20 событий JSON-LD на страницу, с postcode и координатами; фильтр — почтовые области CB, PE, SG, CM, IP, онлайн отбрасываем | M9: https://www.eventbrite.co.uk/d/united-kingdom--cambridge/all-events/?page=N | N9: разрешено | O9: 2026-09-27 | P9: Eventbrite: есть — Eventbrite Affiliate Program (в условиях не указана (обзоры: impact.com))
A10: S009 | B10: Сквозные агрегаторы | C10: Songkick — площадки Кембриджа | D10: Агрегатор | E10: https://www.songkick.com | F10: Концерты по площадкам | G10: Центр | H10: HTML (API для новых партнёров ограничен — проверить) | I10: Еженедельно | J10: 3 | K10: да | L10: Этап 6: не нужен — Songkick: страница города — 404, API для новых партнёров закрыт; концерты покрыты Ents24/Skiddle (S006, S007) | O10: 2026-09-28
A11: S010 | B11: Сквозные агрегаторы | C11: Peterborough Telegraph | D11: СМИ | E11: https://www.peterboroughtoday.co.uk | F11: Север графства: Уиттлси, Питерборо, фены | G11: Час | H11: RSS (уточнить) | I11: Ежедневно | J11: 2 | K11: да | L11: Этап 5: подключён — RSS (HTML сайта — 403); статьи → извлечение через Claude | M11: https://www.peterboroughtoday.co.uk/rss | N11: разрешено | O11: 2026-09-28
A12: S011 | B12: Концерты | C12: Cambridge Corn Exchange | D12: Площадка | E12: https://www.cornex.co.uk/events | F12: Крупные концерты, комедия, балет, городские события | G12: Центр | H12: HTML + JSON-LD | I12: Ежедневно | J12: 1 | K12: да | L12: Сайт Cambridge Live — там же городские события (фейерверки и др.). v0.4: сайт Corn Exchange — cornex.co.uk; список в HTML, на странице события JSON-LD Event с адресом и postcode; cambridgelive.org.uk → билетный сайт | M12: https://www.cornex.co.uk/events | N12: разрешено | O12: 2026-09-27 | P12: события ведут к: Cambridge Live (касса Corn Exchange и Guildhall) — 10 соб.: программы нет
A13: S012 | B13: Концерты | C13: Cambridge Junction | D13: Площадка | E13: https://www.junction.co.uk | F13: Концерты, комедия, клубные вечера, театр | G13: Центр | H13: API + HTML | I13: Ежедневно | J13: 1 | K13: да | L13: v0.4: WP REST, тип cj_events: названия и ссылки, дат нет — даты со страниц; /feed/ — это блог, не афиша Этап 6: подключён — HTML /whats-on/page/N + страницы событий («Event Information»: дата, время, цена); кэш страниц | M13: https://www.junction.co.uk/wp-json/wp/v2/cj_events | N13: разрешено | O13: 2026-09-28 | P13: события ведут к: Spektrix (касса площадки) — 24 соб.: программы нет; Eventbrite — 1 соб.: программа есть; Ticket Tailor — 1 соб.: программы нет
A14: S013 | B14: Концерты | C14: The Portland Arms | D14: Площадка | F14: Небольшие рок/инди-концерты | G14: Центр | H14: Через Ents24/Skiddle | I14: Еженедельно | J14: 2 | K14: нет | L14: Этап 5: не нужен — robots.txt отвечает 403; концерты есть на Ents24/Skiddle (S006/S007) | N14: — | O14: 2026-09-28
A15: S014 | B15: Концерты | C15: Storey's Field Centre (Eddington) | D15: Площадка | F15: Камерная музыка, фолк, джаз | G15: Центр | H15: HTML | I15: Еженедельно | J15: 2 | K15: да | L15: Этап 5: не нужен — фид — 3 новости; события продаются через Eventbrite (S008) и Cambridge Live Tickets (S091) | M15: https://www.storeysfieldcentre.org.uk/feed/ | N15: разрешено | O15: 2026-09-28
A16: S015 | B16: Концерты | C16: West Road Concert Hall | D16: Площадка | F16: Классика, университетские оркестры | G16: Центр | H16: HTML | I16: Еженедельно | J16: 2 | K16: да | L16: Этап 5: не нужен — HTML без JSON-LD; концерты уже приходят из S091, S005, S007, S008 | M16: https://www.westroad.org | N16: разрешено | O16: 2026-09-28
A17: S016 | B17: Концерты | C17: Хоровая музыка колледжей (King's, St John's, Trinity) | D17: Площадка | F17: Evensong, концерты хоров, органные вечера | G17: Центр | H17: HTML по колледжам | I17: Еженедельно | J17: 3 | K17: — | L17: Бесплатно — хороший материал для рубрики «бесплатно» Этап 6: не нужен — хоровая музыка колледжей — покрыто: King's/GSM через Ents24 и University What's On (S048), St John's/Trinity — Visit Cambridge (S001); регулярный evensong в выпуск не идёт | O17: 2026-09-28
A18: S017 | B18: Концерты | C18: Saffron Hall | D18: Площадка | F18: Классика и крупные концерты | G18: Час | H18: HTML | I18: Еженедельно | J18: 2 | K18: да | L18: Этап 5: подключён — HTML-карточки: дата, время, наличие билетов (Nearly full → «мало билетов»), отмены | M18: https://www.saffronhall.com/ | N18: разрешено | O18: 2026-09-28 | P18: события ведут к: Spektrix (касса площадки) — 7 соб.: программы нет
A19: S018 | B19: Спорт — смотреть | C19: Cambridge United | D19: Клуб | E19: https://www.cambridgeunited.com/fixture/list/57 | F19: Матчи Лиги 1, кубки | G19: Центр | H19: iCal (fixtur.es) + HTML | I19: Еженедельно | J19: 1 | K19: да | L19: Календарь сезона публикуется летом целиком. v0.4: у клуба календарь только в HTML (/fixture/list/57); готовый iCal домашних матчей — сторонний fixtur.es, сверять с сайтом клуба | M19: https://ics.fixtur.es/v2/home/cambridge-united-fc.ics | N19: разрешено | O19: 2026-09-27 | P19: события ведут к: своя касса (cambridgeunited.com) — 2 соб.: программы нет
A20: S019 | B20: Спорт — смотреть | C20: Cambridge City FC | D20: Клуб | F20: Нон-лиг футбол | G20: 30 мин | H20: HTML | I20: Еженедельно | J20: 3 | K20: да | L20: Этап 6: не нужен — Cambridge City FC: 8-й уровень (Isthmian North, стадион в Sawston), матчи низкой значимости; сайт лиги без календаря в HTML, Football Web Pages — 403 Этап 6c: подключён — Cambridge City FC: домашние матчи из событий сайта клуба (Wix) → «Спорт → Также играют» Ошибочное прежнее решение: S019 (этап 6: «не нужен, матчи низкой значимости») — отменено владельцем проекта после v5. | O20: 2026-09-29 | P20: события ведут к: своя касса (cambridgecityfc.com) — 1 соб.: программы нет
A21: S020 | B21: Спорт — смотреть | C21: Cambridge Rugby Club | D21: Клуб | F21: Регби, National League | G21: Центр | H21: HTML | I21: Еженедельно | J21: 2 | K21: нет | L21: Этап 5: закрыт — страница-проверка (HTTP 202, бот-защита); обходить не будем Этап 6c: подключён — Cambridge RUFC: сайт клуба за бот-защитой; с 2026/27 — National League 1 (выбыли из Champ Rugby), весь сезон — PDF лиги (nationalleaguerugby.com) Ошибочное прежнее решение: S020 (этап 5: «закрыт — бот-защита») — календарь нашёлся на сайте лиги. | N21: — | O21: 2026-09-29 | P21: события ведут к: продавец не определён — 1 соб.
A22: S021 | B22: Спорт — смотреть | C22: Newmarket Racecourses | D22: Площадка | E22: https://www.thejockeyclub.co.uk/newmarket/events-tickets/ | F22: Скачки, летние концерты Newmarket Nights | G22: 30 мин | H22: JSON-LD | I22: Еженедельно | J22: 1 | K22: да | L22: Сайт Jockey Club | M22: https://www.thejockeyclub.co.uk/newmarket/events-tickets/ | N22: разрешено | O22: 2026-09-27 | P22: The Jockey Club (Newmarket, Huntingdon): есть — Jockey Club Racecourses (Awin (ID 7677))
A23: S022 | B23: Спорт — смотреть | C23: Huntingdon Racecourse | D23: Площадка | F23: Скачки | G23: 30 мин | H23: HTML | I23: Еженедельно | J23: 3 | K23: да | L23: Сайт Jockey Club Этап 6: подключён — Huntingdon Racecourse: JSON-LD на странице событий Jockey Club (как Newmarket S021) | O23: 2026-09-28 | P23: The Jockey Club (Newmarket, Huntingdon): есть — Jockey Club Racecourses (Awin (ID 7677))
A24: S023 | B24: Спорт — смотреть | C24: CUCBC — May Bumps / Lent Bumps | D24: Организатор | F24: Университетские гонки гребных лодок: Lent Bumps (февраль–март) и May Bumps (июнь) | G24: Центр | H24: HTML | I24: Сезонно | J24: 2 | K24: да | L24: Этап 5: ежегодное — Lent/May Bumps — сезонно; RSS новостей есть; даты — через recurring_events | M24: https://www.cucbc.org/rss.xml | N24: разрешено | O24: 2026-09-28
A25: S024 | B25: Спорт — смотреть | C25: Town Bumps (Cambridgeshire Rowing Association) | D25: Организатор | F25: Городские гонки гребных лодок, лето | G25: Центр | H25: HTML | I25: Сезонно | J25: 3 | K25: нет | L25: Этап 6: ежегодное — Town Bumps: сайт Cambridgeshire Rowing Association отвечает 502; летние Town Bumps — в бэклог recurring (дата вручную) | O25: 2026-09-28
A26: S025 | B26: Спорт — смотреть | C26: Varsity-матчи (Oxford vs Cambridge) | D26: Организатор | F26: Регби, гребля и др. дерби университетов | G26: Центр + Лондон | H26: Ручной (календарь) | I26: Ежегодно | J26: 3 | K26: — | L26: Этап 6: вручную — Varsity-матчи: календарь вручную (даты публикуются университетскими клубами), крупные — через статьи | O26: 2026-09-28
A27: S026 | B27: Спорт — участвовать | C27: Chariots of Fire | D27: Организатор | E27: https://www.chariots-of-fire.co.uk/ | F27: Благотворительная эстафета, сентябрь | G27: Центр | H27: JSON-LD (RunThrough) | I27: Ежегодно | J27: 1 | K27: да | L27: Регистрация через RunThrough. v0.4: ежегодно; JSON-LD Event на странице RunThrough; /feed/ сайта — новости Этап 6: ежегодное — через recurring_events (R11) | M27: https://www.runthrough.co.uk/event/chariots-of-fire-september-2026 | N27: разрешено | O27: 2026-09-28
A28: S027 | B28: Спорт — участвовать | C28: RunThrough — события в Кембридже | D28: Организатор / регистрация | E28: https://www.runthrough.co.uk | F28: Забеги, эстафеты | G28: Центр + 30 мин | H28: HTML | I28: Еженедельно | J28: 2 | K28: да | L28: Этап 5: подключён — JSON-LD SportsEvent, но список — 24 ближайших забега по стране; сейчас в регионе 0 (фильтр по почтовым зонам). Ценность низкая — пересмотреть на этапе 6 | M28: https://www.runthrough.co.uk/events-timeline | N28: разрешено | O28: 2026-09-28
A29: S028 | B29: Спорт — участвовать | C29: Cambridge Half Marathon | D29: Организатор | E29: https://cambridgehalfmarathon.com/ | F29: Полумарафон, март | G29: Центр | H29: HTML | I29: Ежегодно | J29: 1 | K29: да | L29: Важен и для рубрики «Практическое» — перекрытия Этап 6: ежегодное — через recurring_events (R03) | M29: https://cambridgehalfmarathon.com/ | N29: разрешено | O29: 2026-09-28
A30: S029 | B30: Спорт — участвовать | C30: Let's Do This — Cambridgeshire | D30: Агрегатор / регистрация | E30: https://www.letsdothis.com | F30: Забеги, триатлоны, велозаезды | G30: Час | H30: HTML | I30: Еженедельно | J30: 2 | K30: нет | L30: Этап 5: закрыт — robots.txt отвечает 403 | N30: — | O30: 2026-09-28
A31: S030 | B31: Фестивали | C31: Cambridge Festival (университет) | D31: Организатор | E31: https://www.festival.cam.ac.uk/events | F31: Наука, гуманитарные темы, весна | G31: Центр | H31: HTML (curl, пауза 10 с) | I31: Сезонно | J31: 1 | K31: да | L31: v0.4: решение после этапа 1: собирать через curl с честным User-Agent и паузой 10 с (robots.txt разрешает, Crawl-delay 10); под браузер не маскироваться; фестиваль в марте Этап 6: ежегодное — Cambridge Festival — весна; дата через recurring_events (R04); коллектор программы — перед фестивалем (март) | M31: https://www.festival.cam.ac.uk/events | N31: разрешено, Crawl-delay 10 | O31: 2026-09-28
A32: S031 | B32: Фестивали | C32: Cambridge Folk Festival | D32: Организатор | E32: https://www.cambridgefolkfestival.co.uk/ | F32: Фолк-фестиваль, лето | G32: Центр | H32: HTML | I32: Ежегодно | J32: 1 | K32: да | L32: v0.4: ежегодно; cambridgelive.org.uk/folk-festival → cambridgefolkfestival.co.uk Этап 6: ежегодное — через recurring_events (R09) | M32: https://www.cambridgefolkfestival.co.uk/ | N32: разрешено | O32: 2026-09-28
A33: S032 | B33: Фестивали | C33: Cambridge Beer Festival | D33: Организатор | E33: https://www.cambridgebeerfestival.com | F33: Пивной фестиваль CAMRA, май | G33: Центр | H33: iCal | I33: Ежегодно | J33: 1 | K33: да | M33: https://www.cambridgebeerfestival.com/events/?ical=1 | N33: разрешено | O33: 2026-09-27 | P33: события ведут к: продавец не определён — 1 соб.
A34: S033 | B34: Фестивали | C34: Strawberry Fair | D34: Организатор | E34: https://strawberry-fair.org.uk/ | F34: Бесплатный фестиваль на Midsummer Common, июнь | G34: Центр | H34: JSON-LD | I34: Ежегодно | J34: 1 | K34: да | L34: Бывали отмены — мониторить. v0.4: JSON-LD Event на главной; /feed/ отдаёт HTML, фида нет | M34: https://strawberry-fair.org.uk/ | N34: разрешено | O34: 2026-09-27
A35: S034 | B35: Фестивали | C35: Whittlesea Straw Bear Festival | D35: Организатор | F35: Средневековый зимний фестиваль, январь | G35: Час | H35: Ручной + Peterborough Telegraph | I35: Ежегодно | J35: 2 | K35: да | L35: Этап 5: ежегодное — уже в recurring_events (R01) | M35: https://www.strawbear.org.uk | N35: разрешено | O35: 2026-09-28
A36: S035 | B36: Фестивали | C36: Cambridge Film Festival | D36: Организатор | F36: Кинофестиваль, осень | G36: Центр | H36: Ручной (ежегодно) | I36: Ежегодно | J36: 2 | K36: да | L36: Этап 5: ежегодное — фестиваль раз в год (осень); HTML без фида — предлагаю добавить в recurring_events | M36: https://www.cambridgefilmfestival.org.uk | N36: разрешено | O36: 2026-09-28
A37: S036 | B37: Фестивали | C37: Cambridge Literary Festival | D37: Организатор | F37: Литфестиваль, весна и осень | G37: Центр | H37: HTML | I37: Сезонно | J37: 2 | K37: нет | L37: Этап 5: закрыт — 403 на сайт и /events | N37: — | O37: 2026-09-28
A38: S037 | B38: Фестивали | C38: Cambridge Science Festival / семейные программы | D38: Организатор | F38: См. Cambridge Festival | G38: Центр | H38: — | I38: — | J38: 3 | K38: — | L38: Дубль — проверить, не слит ли с Cambridge Festival Этап 6: не нужен — Cambridge Science Festival слит с Cambridge Festival — дубль R04 | O38: 2026-09-28
A39: S038 | B39: Ярмарки | C39: Mill Road Winter Fair | D39: Организатор | E39: https://www.millroadwinterfair.org | F39: Уличная ярмарка, первая суббота декабря; Mill Road Fringe в течение года | G39: Центр | H39: RSS | I39: Еженедельно в сезон | J39: 1 | K39: да | L39: Отмены публикуются в соцсетях — нужен контур отмен. v0.4: RSS — новости ярмарки; дату (5.12.2026) и отмены сверять по главной | M39: https://www.millroadwinterfair.org/feed/ | N39: разрешено | O39: 2026-09-27 | P39: события ведут к: продавец не определён — 1 соб.
A40: S039 | B40: Ярмарки | C40: Рождественские маркеты в центре | D40: Организатор | E40: https://www.christmasincambridge.co.uk/ | F40: Сезонные рынки | G40: Центр | H40: HTML | I40: Сезонно | J40: 1 | K40: да | L40: v0.4: сезонно (ноябрь–декабрь); фидов нет Этап 6: ежегодное — Christmas in Cambridge (Parker's Piece: каток, маркет, колесо) — recurring R21, дата со страницы (13.11.2026 – 3.01.2027) | M40: https://www.christmasincambridge.co.uk/ | N40: разрешено | O40: 2026-09-28
...

Sheet Проверка P1
A1: ID | B1: Источник | C1: URL проверен | D1: Способ сбора | E1: Endpoint | F1: Что нашёл | G1: Что не получилось
A2: S001 | B2: Visit Cambridge — events | C2: да | D2: API + HTML | E2: https://www.visitcambridge.org/wp-json/vc-map/v1/events | F2: https://www.visitcambridge.org — 200; alternate-фиды: https://www.visitcambridge.org/wp-json/wp/v2/pages/26, https://www.visitcambridge.org/wp-json/oembed/1.0/embed?url=https%3A%2F%2Fwww.visitcambridge.org%2F; WordPress https://www.visitcambridge.org/whats-on/ — 200; alternate-фиды: https://www.visitcambridge.org/wp-json/wp/v2/pages/553, https://www.visitcambridge.org/wp-json/oembed/1.0/embed?url=https%3A%2F%2Fwww.visitcambridge.org%2Fwhats-on%2F; WordPress https://www.visitcambridge.org/event-categories/festivals/ — 200; alternate-фиды: https://www.visitcambridge.org/event-categories/festivals/feed/; WordPress https://www.visitcambridge.org/wp-json/vc-map/v1/events — 200; JSON
A3: S002 | B3: What's On In Cambridge | C3: да | D3: RSS | E3: https://www.whatsonincambridge.com/feed/ | F3: https://www.whatsonincambridge.com/__superjs/challenge?u=%2Fevents%2F — 200 https://www.whatsonincambridge.com/feed/ — 200; фид, записей: 10 | G3: https://www.whatsonincambridge.com/events/ — JS-проверка «SuperJS» (бот-блок), HTML без браузера недоступен
A4: S003 | B4: Cambridge Independent — What's On | C4: да | D4: RSS | E4: https://www.cambridgeindependent.co.uk/_api/rss/cambridge_independent_whatson_feed.xml | F4: https://www.cambridgeindependent.co.uk/whats-on/ — 200 https://www.cambridgeindependent.co.uk/_api/rss/cambridge_independent_whatson_feed.xml — 200; фид, записей: 20
A5: S004 | B5: Cambridge News / CambridgeshireLive | C5: да | D5: RSS | E5: https://www.cambridge-news.co.uk/whats-on/?service=rss | F5: https://www.cambridge-news.co.uk — 200; alternate-фиды: https://www.cambridge-news.co.uk/rss.xml https://www.cambridge-news.co.uk/whats-on/ — 200; alternate-фиды: https://www.cambridge-news.co.uk/whats-on/rss.xml; билетная система: ecal https://www.cambridge-news.co.uk/?service=rss — 200; фид, записей: 25 https://www.cambridge-news.co.uk/whats-on/?service=rss — 200; фид, записей: 15 https://www.cambridge-news.co.uk/whats-on/?service=rss — 200; фид, записей: 15
A6: S005 | B6: Cambridge 105 — события | C6: да | D6: iCal | E6: https://cambridge105.co.uk/whatson/?ical=1 | F6: https://cambridge105.co.uk — 200; alternate-фиды: https://cambridge105.co.uk/whatson/?ical=1, https://cambridge105.co.uk/wp-json/wp/v2/pages/44141, https://cambridge105.co.uk/wp-json/oembed/1.0/embed?url=https%3A%2F%2Fcambridge105.co.uk%2F; WordPress https://cambridge105.co.uk/events/ — 200; alternate-фиды: https://cambridge105.co.uk/whatson/?ical=1, https://cambridge105.co.uk/wp-json/wp/v2/media/75261, https://cambridge105.co.uk/wp-json/oembed/1.0/embed?url=https%3A%2F%2Fcambridge105.co.uk%2Fevents%2F; WordPress https://cambridge105.co.uk/feed/ — 200; фид, записей: 30 https://cambridge105.co.uk/events/?ical=1 — 200; iCal, событий: 22 https://cambridge105.co.uk/wp-json/tribe/events/v1/events — 200; JSON https://cambridge105.co.uk/whatson/?ical=1 — 200; iCal, событий: 22
A7: S006 | B7: Ents24 — Cambridge | C7: да | D7: JSON-LD | E7: https://www.ents24.com/whatson/cambridge | F7: https://www.ents24.com/whatson/cambridge — 200; JSON-LD Event: 37; билетная система: ents24, gigantic
A8: S007 | B8: Skiddle — Cambridge | C8: да | D8: JSON-LD | E8: https://www.skiddle.com/whats-on/Cambridge/ | F8: https://www.skiddle.com/whats-on/Cambridge/ — 200; JSON-LD Event: 49; билетная система: ecal, skiddle https://www.skiddle.com/api/ — 200; билетная система: skiddle
A9: S008 | B9: Eventbrite — Cambridge | C9: да | D9: JSON-LD | E9: https://www.eventbrite.co.uk/d/united-kingdom--cambridge/all-events/?page=N | F9: https://www.eventbrite.co.uk — 200; билетная система: eventbrite https://www.eventbrite.co.uk/d/united-kingdom--cambridge/all-events/ — 200; JSON-LD Event: 20; билетная система: eventbrite
A10: S011 | B10: Cambridge Corn Exchange | C10: да | D10: HTML + JSON-LD | E10: https://www.cornex.co.uk/events | F10: https://www.cambridgelivetickets.co.uk/ — 200 https://www.cornex.co.uk — 200 https://www.cornex.co.uk/events — 200 https://www.cambridgelivetickets.co.uk — 200 https://www.cornex.co.uk/events/alison-moyet-2 — 200; JSON-LD Event: 1
A11: S012 | B11: Cambridge Junction | C11: да | D11: API + HTML | E11: https://www.junction.co.uk/wp-json/wp/v2/cj_events | F11: https://www.junction.co.uk — 200; alternate-фиды: https://www.junction.co.uk/feed/, https://www.junction.co.uk/comments/feed/, https://www.junction.co.uk/wp-json/oembed/1.0/embed?url=https%3A%2F%2Fwww.junction.co.uk%2F; WordPress; билетная система: ecal, spektrix https://www.junction.co.uk/whats-on/ — 200; alternate-фиды: https://www.junction.co.uk/feed/, https://www.junction.co.uk/comments/feed/, https://www.junction.co.uk/wp-json/oembed/1.0/embed?url=https%3A%2F%2Fwww.junction.co.uk%2Fwhats-on%2F; WordPress; билетная система: ecal, spektrix https://www.junction.co.uk/wp-json/wp/v2/cj_events?per_page=20 — 200; JSON https://www.junction.co.uk/feed/ — 200; фид, записей: 12
A12: S018 | B12: Cambridge United | C12: да | D12: iCal (fixtur.es) + HTML | E12: https://ics.fixtur.es/v2/home/cambridge-united-fc.ics | F12: https://www.cambridgeunited.com — 200 https://fixtur.es/en/team/cambridge-united-fc/home — 200; JSON-LD Event: 27 https://www.cambridgeunited.com/fixture/list/57 — 200 https://ics.fixtur.es/v2/home/cambridge-united-fc.ics — 200; iCal, событий: 188
A13: S021 | B13: Newmarket Racecourses | C13: да | D13: JSON-LD | E13: https://www.thejockeyclub.co.uk/newmarket/events-tickets/ | F13: https://www.thejockeyclub.co.uk/newmarket/ — 200 https://www.thejockeyclub.co.uk/newmarket/events-tickets/ — 200; JSON-LD Event: 14
A14: S026 | B14: Chariots of Fire | C14: да | D14: JSON-LD (RunThrough) | E14: https://www.runthrough.co.uk/event/chariots-of-fire-september-2026 | F14: https://www.chariots-of-fire.co.uk/ — 200; alternate-фиды: https://www.chariots-of-fire.co.uk/feed/, https://www.chariots-of-fire.co.uk/comments/feed/, https://www.chariots-of-fire.co.uk/wp-json/wp/v2/pages/21; WordPress https://www.chariots-of-fire.co.uk/feed/ — 200; фид, записей: 10 https://www.runthrough.co.uk/event/chariots-of-fire-september-2026 — 200; JSON-LD Event: 1
A15: S028 | B15: Cambridge Half Marathon | C15: да | D15: HTML | E15: https://cambridgehalfmarathon.com/ | F15: https://cambridgehalfmarathon.com/ — 200
A16: S030 | B16: Cambridge Festival (университет) | C16: да | D16: HTML (curl, пауза 10 с) | E16: https://www.festival.cam.ac.uk/events | F16: https://www.festival.cam.ac.uk/events — 200 через curl, robots.txt разрешает (Crawl-delay: 10); фидов и JSON-LD нет | G16: Pantheon отдаёт 403 Python-клиенту httpx (и на robots.txt), curl с тем же User-Agent — 200: блок по отпечатку клиента
A17: S031 | B17: Cambridge Folk Festival | C17: да | D17: HTML | E17: https://www.cambridgefolkfestival.co.uk/ | F17: https://www.cambridgefolkfestival.co.uk/ — 200 https://www.cambridgefolkfestival.co.uk/ — 200
A18: S032 | B18: Cambridge Beer Festival | C18: да | D18: iCal | E18: https://www.cambridgebeerfestival.com/events/?ical=1 | F18: https://www.cambridgebeerfestival.com — 200; JSON-LD Event: 2; alternate-фиды: https://www.cambridgebeerfestival.com/events/?ical=1; WordPress + The Events Calendar; билетная система: ecal
A19: S033 | B19: Strawberry Fair | C19: да | D19: JSON-LD | E19: https://strawberry-fair.org.uk/ | F19: https://strawberry-fair.org.uk/ — 200; JSON-LD Event: 1 https://strawberry-fair.org.uk/feed/ — 200; JSON-LD Event: 1
A20: S038 | B20: Mill Road Winter Fair | C20: да | D20: RSS | E20: https://www.millroadwinterfair.org/feed/ | F20: https://www.millroadwinterfair.org — 200; alternate-фиды: https://www.millroadwinterfair.org/feed/, https://www.millroadwinterfair.org/comments/feed/, https://www.millroadwinterfair.org/wp-json/wp/v2/pages/22; WordPress https://www.millroadwinterfair.org/feed/ — 200; фид, записей: 0
A21: S039 | B21: Рождественские маркеты в центре | C21: да | D21: HTML | E21: https://www.christmasincambridge.co.uk/ | F21: https://www.christmasincambridge.co.uk/ — 200 https://www.visitcambridge.org/event/christmas-in-cambridge/ — 200; alternate-фиды: https://www.visitcambridge.org/wp-json/oembed/1.0/embed?url=https%3A%2F%2Fwww.visitcambridge.org%2Fevent%2Fchristmas-in-cambridge%2F; WordPress
A22: S041 | B22: Cambridge Arts Theatre | C22: проверить | D22: Через Ents24 (S006) | G22: https://www.artstheatre.co.uk — 403, Cloudflare challenge (cf-mitigated) и для httpx, и для curl
A23: S042 | B23: ADC Theatre | C23: да | D23: iCal | E23: https://www.camdram.net/venues/adc-theatre/diary.ics | F23: https://www.adctheatre.com — 200; билетная система: spektrix https://www.adctheatre.com/whats-on/ — 200; билетная система: spektrix https://www.camdram.net/venues/adc-theatre/diary.ics — 200; iCal, событий: 28 https://www.camdram.net/venues/adc-theatre/diary.json — 200; JSON
A24: S045 | B24: Arts Picturehouse | C24: да | D24: HTML | E24: https://www.picturehouses.com/cinema/arts-picturehouse-cambridge | F24: https://www.picturehouses.com/cinema/arts-picturehouse-cambridge — 200; билетная система: ecal
A25: S047 | B25: Talks.cam | C25: да | D25: iCal | E25: https://talks.cam.ac.uk/show/ics/{5606,5462,5358,5769,23088}/ | F25: https://talks.cam.ac.uk — 200 https://talks.cam.ac.uk/document/documentation/ — 200 https://talks.cam.ac.uk/show/ics/5606/ — 200; iCal, событий: 15 https://talks.cam.ac.uk/show/ics/5462/ — 200; iCal, событий: 8 https://talks.cam.ac.uk/show/ics/5358/ — 200; iCal, событий: 8 https://talks.cam.ac.uk/show/ics/5769/ — 200; iCal, событий: 7 https://talks.cam.ac.uk/show/ics/23088/ — 200; iCal, событий: 55
A26: S048 | B26: University of Cambridge — What's On | C26: да | D26: HTML | E26: https://www.admin.cam.ac.uk/whatson/ | F26: https://www.admin.cam.ac.uk/whatson/ — 200 | G26: webservices.admin.cam.ac.uk (iCal 76 событий, RSS) — robots.txt: Disallow: / — не собираем без решения https://www.cam.ac.uk/whats-on — Pantheon 403 для httpx
A27: S050 | B27: Fitzwilliam Museum | C27: да | D27: RSS (выставки) + HTML (события) | E27: https://fitzmuseum.cam.ac.uk/feeds/exhibitions | F27: https://fitzmuseum.cam.ac.uk — 200; alternate-фиды: https://fitzmuseum.cam.ac.uk/feeds/news, https://fitzmuseum.cam.ac.uk/feeds/vacancies, https://fitzmuseum.cam.ac.uk/feeds/exhibitions https://fitzmuseum.cam.ac.uk/events — 200; alternate-фиды: https://fitzmuseum.cam.ac.uk/feeds/news, https://fitzmuseum.cam.ac.uk/feeds/vacancies, https://fitzmuseum.cam.ac.uk/feeds/exhibitions https://fitzmuseum.cam.ac.uk/feeds/exhibitions — 200; фид, записей: 20
A28: S051 | B28: Kettle's Yard | C28: да | D28: HTML | E28: https://www.kettlesyard.cam.ac.uk/whats-on/ | F28: https://www.kettlesyard.cam.ac.uk — 200 https://www.kettlesyard.cam.ac.uk/whats-on/ — 200 | G28: https://www.kettlesyard.cam.ac.uk/feed/ — 500 https://www.kettlesyard.co.uk — ConnectError: [SSL: CERTIFICATE_VERIFY_FAILED] certificate verify failed: Hostname mismatch, certificate is not valid for 'www.kettlesyard.co.uk'. (_ssl.c:1016) https://www.kettlesyard.co.uk/events/ — ConnectError: [SSL: CERTIFICATE_VERIFY_FAILED] certificate verify failed: Hostname mismatch, certificate is not valid for 'www.kettlesyard.co.uk'. (_ssl.c:1016) https://www.kettlesyard.co.uk/feed/ — ConnectError: [SSL: CERTIFICATE_VERIFY_FAILED] certificate verify failed: Hostname mismatch, certificate is not valid for 'www.kettlesyard.co.uk'. (_ssl.c:1016)
A29: S052 | B29: University of Cambridge Museums (сводный) | C29: да | D29: HTML | E29: https://www.museums.cam.ac.uk/whats-on | F29: https://www.museums.cam.ac.uk — 200 https://www.museums.cam.ac.uk/whats-on — 200
A30: S056 | B30: Семейные программы музеев | C30: проверить | D30: Производный (тег «дети») | G30: своего URL нет по замыслу
A31: S062 | B31: Комедия на Corn Exchange / Junction / ADC | C31: проверить | D31: Производный (тег «комедия») | G31: своего URL нет по замыслу
A32: S065 | B32: Open Cambridge | C32: да | D32: HTML (curl, пауза 10 с) | E32: https://www.opencambridge.cam.ac.uk/ | F32: https://www.opencambridge.cam.ac.uk/ — 200 через curl; фидов нет | G32: Pantheon отдаёт 403 Python-клиенту httpx, curl — 200
A33: S069 | B33: Cambridge University Botanic Garden | C33: да | D33: HTML | E33: https://www.botanic.cam.ac.uk/whats-on/ | F33: https://www.botanic.cam.ac.uk — 200; alternate-фиды: https://www.botanic.cam.ac.uk/wp-json/oembed/1.0/embed?url=https%3A%2F%2Fwww.botanic.cam.ac.uk%2F, https://www.botanic.cam.ac.uk/wp-json/wp/v2/pages/6; WordPress https://www.botanic.cam.ac.uk/whats-on/ — 200; WordPress
A34: S070 | B34: National Trust: Wimpole, Anglesey Abbey, Wicken Fen | C34: проверить | D34: Ручной сезонный | E34: https://www.nationaltrust.org.uk/visit/cambridgeshire/wimpole-estate/events | F34: https://www.nationaltrust.org.uk/visit/cambridgeshire/wimpole-estate/events — 200 https://www.nationaltrust.org.uk/visit/cambridgeshire/anglesey-abbey-gardens-and-lode-mill/events — 200 https://www.nationaltrust.org.uk/visit/cambridgeshire/wicken-fen-nature-reserve/events — 200 | G34: nationaltrust.org.uk — после 1–2 запросов отдаёт страницу бот-защиты Radware Wicken Fen: /wicken-fen-nature-reserve/events — страница 404; верный адрес не подтверждён
A35: S072 | B35: Cambridge City Council — городские события | C35: да | D35: HTML | E35: https://www.camcityevents.co.uk/events | F35: https://www.cambridge.gov.uk — 200 https://www.cambridge.gov.uk/summer-events — 200 https://www.camcityevents.co.uk/events — 200 | G35: https://www.cambridge.gov.uk/fireworks — 404
A36: S081 | B36: Thriplow Daffodil Weekend | C36: да | D36: HTML | E36: https://www.thriplowdaffodils.org.uk | F36: https://www.thriplowdaffodils.org.uk — 200
A37: S082 | B37: Cambridge Dragon Boat Festival (ACT) | C37: да | D37: HTML | E37: https://act4addenbrookes.org.uk/dragonboat/ | F37: https://act4addenbrookes.org.uk — 200; alternate-фиды: https://act4addenbrookes.org.uk/feed/, https://act4addenbrookes.org.uk/comments/feed/, https://act4addenbrookes.org.uk/wp-json/oembed/1.0/embed?url=https%3A%2F%2Fact4addenbrookes.org.uk%2F; WordPress https://act4addenbrookes.org.uk/events/cambridge-dragon-boat-festival-2026/ — 200; alternate-фиды: https://act4addenbrookes.org.uk/feed/, https://act4addenbrookes.org.uk/comments/feed/, https://act4addenbrookes.org.uk/wp-json/oembed/1.0/embed?url=https%3A%2F%2Fact4addenbrookes.org.uk%2Fevents%2Fcambridge-dragon-boat-festival-2026%2F; WordPress
A38: S087 | B38: The Cambridge Foodies | C38: да | D38: RSS | E38: https://cambridgefoodies.me.uk/feed/ | F38: https://cambridgefoodies.me.uk — 200 в первом проходе, WordPress, alternate RSS /feed/ https://cambridgefoodies.me.uk/feed/ — 200 через HTTP/2 | G38: WordPress.com отвечает 429 при повторных запросах (и HTTP/1.1-клиенту httpx) — нужны HTTP/2, редкие запросы и бэк-офф
A39: S089 | B39: Town and Gown 10k | C39: проверить | D39: Через Cambridge News (S004) и Cambridge 105 (S005) | G39: townandgown10k.com и musculardystrophyuk.org — Cloudflare 403 для любого бот-клиента, включая robots.txt
A40: S090 | B40: DesignMyNight — Cambridge | C40: нет | D40: — (robots.txt запрещает) | E40: https://www.designmynight.com/cambridge | F40: https://www.designmynight.com/cambridge — 200 | G40: robots.txt: Disallow: /cambridge/whats-on и Disallow: /api/ — раздел событий закрыт для роботов разрешённые страницы /cambridge — каталог заведений, событий и JSON-LD Event нет
...

Sheet Контрольные события
A1: ID | B1: Событие | C1: Когда | D1: Где искать | E1: Ключевые слова
A2: C1 | B2: Домашние матчи Cambridge United | C2: весь сезон | D2: S018 (fixtur.es), будущие домашние матчи | E2: Cambridge United
A3: C2 | B3: Mill Road Winter Fair | C3: 2026-12-05 | D3: S038 (сайт ярмарки), Cambridge 105, Cambridge News | E3: Mill Road Winter Fair, Winter Fair
A4: C3 | B4: Town and Gown 10k | C4: октябрь 2026 | D4: через Cambridge News (S004) и Cambridge 105 (S005) — сайт закрыт для ботов | E4: Town and Gown 10, Town & Gown 10, Bidwells Cambridge 10k, Cambridge 10k
A5: C4 | B5: Whittlesea Straw Bear Festival | C5: январь 2027 | D5: Cambridge 105, Visit Cambridge, новости | E5: Straw Bear
A6: C5 | B6: Thriplow Daffodil Weekend | C6: март 2027 | D6: Cambridge 105 | E6: Thriplow, Daffodil Weekend
A7: C6 | B7: Публичные лекции talks.cam | C7: постоянно | D7: S047, списки Major Public Lectures, Darwin College и др. | E7: S047
A8: C7 | B8: Открытия на Mill Road: Catte Latte, Hungarian Soul | C8: уже прошли (архив) | D8: Cambridge Foodies — поток «новое в городе» | E8: Catte Latte, Hungarian Soul
A9: C8 | B9: Cambridge Oktoberfest, Jesus Green | C9: 2026-09-25 – 2026-09-26 | D9: Eventbrite / Skiddle / Ents24 / Cambridge 105 / новости, если ещё видно | E9: Oktoberfest

Sheet Сводка
A1: Категория | B1: Всего источников | C1: Приоритет 1 | D1: URL проверен | E1: Осталось проверить
A2: Сквозные агрегаторы | B2: =COUNTIF(Источники!$B$2:$B$500,A2) | C2: =COUNTIFS(Источники!$B$2:$B$500,A2,Источники!$J$2:$J$500,1) | D2: =COUNTIFS(Источники!$B$2:$B$500,A2,Источники!$K$2:$K$500,"да") | E2: =B2-D2
A3: Концерты | B3: =COUNTIF(Источники!$B$2:$B$500,A3) | C3: =COUNTIFS(Источники!$B$2:$B$500,A3,Источники!$J$2:$J$500,1) | D3: =COUNTIFS(Источники!$B$2:$B$500,A3,Источники!$K$2:$K$500,"да") | E3: =B3-D3
A4: Спорт — смотреть | B4: =COUNTIF(Источники!$B$2:$B$500,A4) | C4: =COUNTIFS(Источники!$B$2:$B$500,A4,Источники!$J$2:$J$500,1) | D4: =COUNTIFS(Источники!$B$2:$B$500,A4,Источники!$K$2:$K$500,"да") | E4: =B4-D4
A5: Спорт — участвовать | B5: =COUNTIF(Источники!$B$2:$B$500,A5) | C5: =COUNTIFS(Источники!$B$2:$B$500,A5,Источники!$J$2:$J$500,1) | D5: =COUNTIFS(Источники!$B$2:$B$500,A5,Источники!$K$2:$K$500,"да") | E5: =B5-D5
A6: Фестивали | B6: =COUNTIF(Источники!$B$2:$B$500,A6) | C6: =COUNTIFS(Источники!$B$2:$B$500,A6,Источники!$J$2:$J$500,1) | D6: =COUNTIFS(Источники!$B$2:$B$500,A6,Источники!$K$2:$K$500,"да") | E6: =B6-D6
A7: Ярмарки | B7: =COUNTIF(Источники!$B$2:$B$500,A7) | C7: =COUNTIFS(Источники!$B$2:$B$500,A7,Источники!$J$2:$J$500,1) | D7: =COUNTIFS(Источники!$B$2:$B$500,A7,Источники!$K$2:$K$500,"да") | E7: =B7-D7
A8: Театр | B8: =COUNTIF(Источники!$B$2:$B$500,A8) | C8: =COUNTIFS(Источники!$B$2:$B$500,A8,Источники!$J$2:$J$500,1) | D8: =COUNTIFS(Источники!$B$2:$B$500,A8,Источники!$K$2:$K$500,"да") | E8: =B8-D8
A9: Кино | B9: =COUNTIF(Источники!$B$2:$B$500,A9) | C9: =COUNTIFS(Источники!$B$2:$B$500,A9,Источники!$J$2:$J$500,1) | D9: =COUNTIFS(Источники!$B$2:$B$500,A9,Источники!$K$2:$K$500,"да") | E9: =B9-D9
A10: Лекции | B10: =COUNTIF(Источники!$B$2:$B$500,A10) | C10: =COUNTIFS(Источники!$B$2:$B$500,A10,Источники!$J$2:$J$500,1) | D10: =COUNTIFS(Источники!$B$2:$B$500,A10,Источники!$K$2:$K$500,"да") | E10: =B10-D10
A11: Выставки и музеи | B11: =COUNTIF(Источники!$B$2:$B$500,A11) | C11: =COUNTIFS(Источники!$B$2:$B$500,A11,Источники!$J$2:$J$500,1) | D11: =COUNTIFS(Источники!$B$2:$B$500,A11,Источники!$K$2:$K$500,"да") | E11: =B11-D11
A12: Детям и семьям | B12: =COUNTIF(Источники!$B$2:$B$500,A12) | C12: =COUNTIFS(Источники!$B$2:$B$500,A12,Источники!$J$2:$J$500,1) | D12: =COUNTIFS(Источники!$B$2:$B$500,A12,Источники!$K$2:$K$500,"да") | E12: =B12-D12
A13: Еда и напитки | B13: =COUNTIF(Источники!$B$2:$B$500,A13) | C13: =COUNTIFS(Источники!$B$2:$B$500,A13,Источники!$J$2:$J$500,1) | D13: =COUNTIFS(Источники!$B$2:$B$500,A13,Источники!$K$2:$K$500,"да") | E13: =B13-D13
... A22: Практическое | B22: =COUNTIF(Источники!$B$2:$B$500,A22) | C22: =COUNTIFS(Источники!$B$2:$B$500,A22,Источники!$J$2:$J$500,1) | D22: =COUNTIFS(Источники!$B$2:$B$500,A22,Источники!$K$2:$K$500,"да") | E22: =B22-D22
A23: Итого | B23: =SUM(B2:B22) | C23: =SUM(C2:C22) | D23: =SUM(D2:D22) | E23: =SUM(E2:E22)

Sheet Схема события
A1: Поле | B1: Тип | C1: Обязательное | D1: Пример | E1: Комментарий
A2: event_id | B2: текст | C2: да | D2: EV-2026-000123 | E2: Внутренний ID
A3: title | B3: текст | C3: да | D3: Cambridge United vs AFC Wimbledon
A4: category | B4: список | C4: да | D4: Спорт — смотреть | E4: Из листа «Категории и теги»
A5: date_start | B5: дата | C5: да | D5: 2026-09-26
A6: time_start | B6: время | C6: да, если известно | D6: 15:00 | E6: Пусто = весь день
A7: date_end | B7: дата | C7: нет | D7: 2026-09-26 | E7: Для многодневных
A8: time_end | B8: время | C8: нет | D8: 17:00
A9: venue_name | B9: текст | C9: да | D9: Abbey Stadium
A10: address | B10: текст | C10: да | D10: Newmarket Road, Cambridge | E10: Точный адрес
A11: postcode | B11: текст | C11: да | D11: (заполнять из источника) | E11: Для карты и расчёта зоны
A12: lat / lon | B12: число | C12: нет | D12: 52.21, 0.15 | E12: Геокодирование по postcode
A13: zone | B13: список | C13: да | D13: Центр | E13: Тег: Центр / до 30 мин / до часа — считается автоматически
A14: price_from | B14: число, £ | C14: нет | D14: 0 | E14: 0 = бесплатно
A15: price_tag | B15: список | C15: да | D15: бесплатно / до £10 / дороже
A16: audience | B16: список (несколько) | C16: нет | D16: дети 5–12; семьи
A17: booking | B17: список | C17: да | D17: без билетов / бронировать / продажа скоро
A18: status | B18: список | C18: да | D18: по плану | E18: по плану / перенесено / отменено / sold out
A19: ticket_url | B19: URL | C19: нет | E19: Здесь партнёрская ссылка, если есть
A20: source_id | B20: ссылка | C20: да | D20: S018 | E20: ID из листа «Источники»
A21: source_url | B21: URL | C21: да | E21: Страница события у первоисточника
A22: description_short | B22: текст | C22: да | E22: 2–3 предложения своими словами (не копировать)
A23: score | B23: число 1–10 | C23: нет | D23: 8 | E23: Оценка LLM «стоит ли внимания»
A24: last_checked | B24: дата-время | C24: да | E24: Когда контур отмен последний раз проверял

Sheet Категории и теги
A1: Ось | B1: Значение
A2: Категория | B2: Концерты
A3: Категория | B3: Спорт — смотреть
A4: Категория | B4: Спорт — участвовать
A5: Категория | B5: Фестивали
A6: Категория | B6: Ярмарки
A7: Категория | B7: Театр
A8: Категория | B8: Кино
A9: Категория | B9: Лекции
A10: Категория | B10: Выставки и музеи
A11: Категория | B11: Детям и семьям
A12: Категория | B12: Еда и напитки
... A39: Статус | B39: sold out

Sheet Проверка P2
A1: ID | B1: Источник | C1: Состояние | D1: Решение | E1: Способ | F1: Endpoint | G1: Примечание
A2: S010 | B2: Peterborough Telegraph | C2: живой | D2: подключён | E2: RSS | F2: https://www.peterboroughtoday.co.uk/rss | G2: RSS (HTML сайта — 403); статьи → извлечение через Claude
A3: S013 | B3: The Portland Arms | C3: закрыт | D3: не нужен | G3: robots.txt отвечает 403; концерты есть на Ents24/Skiddle (S006/S007)
A4: S014 | B4: Storey's Field Centre (Eddington) | C4: живой | D4: не нужен | E4: RSS | F4: https://www.storeysfieldcentre.org.uk/feed/ | G4: фид — 3 новости; события продаются через Eventbrite (S008) и Cambridge Live Tickets (S091)
A5: S015 | B5: West Road Concert Hall | C5: живой | D5: не нужен | E5: HTML | F5: https://www.westroad.org | G5: HTML без JSON-LD; концерты уже приходят из S091, S005, S007, S008
A6: S017 | B6: Saffron Hall | C6: живой | D6: подключён | E6: HTML | F6: https://www.saffronhall.com/ | G6: HTML-карточки: дата, время, наличие билетов (Nearly full → «мало билетов»), отмены
A7: S020 | B7: Cambridge Rugby Club | C7: закрыт | D7: закрыт | G7: страница-проверка (HTTP 202, бот-защита); обходить не будем
A8: S023 | B8: CUCBC — May Bumps / Lent Bumps | C8: живой | D8: ежегодное | E8: RSS | F8: https://www.cucbc.org/rss.xml | G8: Lent/May Bumps — сезонно; RSS новостей есть; даты — через recurring_events
A9: S027 | B9: RunThrough — события в Кембридже | C9: живой | D9: подключён | E9: JSON-LD | F9: https://www.runthrough.co.uk/events-timeline | G9: JSON-LD SportsEvent, но список — 24 ближайших забега по стране; сейчас в регионе 0 (фильтр по почтовым зонам). Ценность низкая — пересмотреть на этапе 6
A10: S029 | B10: Let's Do This — Cambridgeshire | C10: закрыт | D10: закрыт | G10: robots.txt отвечает 403
A11: S034 | B11: Whittlesea Straw Bear Festival | C11: живой | D11: ежегодное | E11: HTML | F11: https://www.strawbear.org.uk | G11: уже в recurring_events (R01)
A12: S035 | B12: Cambridge Film Festival | C12: живой | D12: ежегодное | E12: HTML | F12: https://www.cambridgefilmfestival.org.uk | G12: фестиваль раз в год (осень); HTML без фида — предлагаю добавить в recurring_events
A13: S036 | B13: Cambridge Literary Festival | C13: закрыт | D13: закрыт | G13: 403 на сайт и /events
A14: S044 | B14: Постановки в садах колледжей (лето) | C14: живой | D14: ежегодное | E14: HTML | F14: https://cambridgeshakespeare.com/ | G14: летний сезон постановок; ручной сезонный календарь
A15: S046 | B15: Кино под открытым небом (летние сезоны) | C15: нет событий | D15: ежегодное | E15: HTML | F15: https://www.cambridgefilmfestival.org.uk | G15: летние показы; адрес организатора не подтверждён — ручной сезонный
A16: S049 | B16: Cambridge Union | C16: живой | D16: не нужен | E16: RSS | F16: https://cus.org/feed | G16: мероприятия в основном для членов Union; публичные крупные гости попадают в новости
A17: S051 | B17: Kettle's Yard | C17: живой | D17: подключён | E17: HTML | F17: https://www.kettlesyard.cam.ac.uk/whats-on/ | G17: приоритет 1, коллектора не было: HTML страниц событий (контрольный пример этапа 5)
A18: S053 | B18: IWM Duxford | C18: закрыт | D18: закрыт | G18: iwm.org.uk — 403 (бот-защита) на все страницы; в Ents24/Skiddle Duxford не найден
A19: S054 | B19: Cambridge Science Centre | C19: живой | D19: отложен | E19: RSS | F19: https://www.cambridgesciencecentre.org/whats-on/feed/ | G19: WordPress, тип записей events без дат в API — нужен разбор HTML (детские события — ценно)
A20: S055 | B20: Библиотеки Cambridgeshire | C20: живой | D20: отложен | E20: HTML | F20: https://www.cambridgeshire.gov.uk/residents/libraries-leisure-culture/libraries | G20: Contensis, события библиотек — на сторонних сервисах; нужен разбор
A21: S057 | B21: Eat Cambridge | C21: живой | D21: ежегодное | E21: RSS | F21: https://eat-cambridge.co.uk/feed/ | G21: фестиваль в мае; фид — 3 записи
A22: S058 | B22: Открытия ресторанов | C22: — | D22: не нужен | G22: производный источник: открытия через S092/S093 (извлечение из статей)
A23: S066 | B23: Heritage Open Days | C23: живой | D23: ежегодное | E23: HTML | F23: https://www.heritageopendays.org.uk | G23: Heritage Open Days — сентябрь; поиск по региону в HTML
A24: S067 | B24: National Garden Scheme | C24: живой | D24: отложен | E24: HTML | F24: https://ngs.org.uk | G24: findagarden.ngs.org.uk — сезон весна–лето; разбор HTML
A25: S071 | B25: Ely Cathedral | C25: живой | D25: отложен | E25: HTML | F25: https://www.elycathedral.org | G25: Spektrix без JSON-LD; часть концертов уже из Ents24/Skiddle (S128/S129) и Eventbrite
A26: S075 | B26: Воркшопы в музеях | C26: — | D26: не нужен | G26: производный (музеи)
A27: S076 | B27: Love Mill Road / Mill Road Fringe | C27: живой | D27: отложен | E27: RSS | F27: https://www.millroadwinterfair.org/feed/ | G27: Mill Road Fringe — сезонно; страница WordPress без событийных данных
A28: S077 | B28: Районные FB-группы и Nextdoor | C28: — | D28: не нужен | G28: соцсети — по правилам не парсим
A29: S078 | B29: Перекрытия дорог (county council / one.network) | C29: закрыт | D29: закрыт | G29: robots.txt запрещает
A30: S079 | B30: Greater Anglia / Thameslink / National Rail | C30: живой | D30: не нужен | E30: HTML | F30: https://www.nationalrail.co.uk | G30: не события (транспорт); вернуться к этому, если понадобится практический блок
A31: S083 | B31: «Nihao! China» Cambridge Dragon Boat Festival | C31: живой | D31: ежегодное | E31: JSON-LD | F31: https://www.eventbrite.com/e/nihao-china-cambridge-dragon-boat-festival-2026-tickets-1985873566295 | G31: фестиваль в июне; билеты на Eventbrite (S008)
A32: S084 | B32: Cambridgeshire Cats (американский футбол) | C32: живой | D32: отложен | E32: RSS | F32: https://cambridgeshirecats.com/feed/ | G32: сайт WordPress (новости), страницы расписания нет; сезон BAFA — весна–лето, сейчас матчей нет
A33: S086 | B33: Addenbrooke's Charitable Trust — события | C33: живой | D33: отложен | E33: RSS | F33: https://act4addenbrookes.org.uk/feed/ | G33: WordPress events + RSS; благотворительные забеги и челленджи — разбор HTML
A34: S088 | B34: parkrun — Cambridge, Wimpole и др. | C34: закрыт | D34: закрыт | G34: parkrun.org.uk: robots.txt отвечает 403 — считаем запретом; регулярные забеги — статичный справочник вручную
A35: S098 | B35: South Cambridgeshire District Council | C35: живой | D35: отложен | E35: HTML | F35: https://www.scambs.gov.uk | G35: страница /events есть, событийных данных нет
A36: S099 | B36: East Cambridgeshire District Council | C36: живой | D36: отложен | E36: HTML | F36: https://eastcambs.gov.uk/ | G36: Drupal, /events без структурированных данных
A37: S100 | B37: Huntingdonshire District Council | C37: живой | D37: отложен | E37: HTML | F37: https://www.huntingdonshire.gov.uk | G37: события Hinchingbrooke Country Park — через TicketSource; разбор HTML
A38: S101 | B38: Fenland District Council | C38: закрыт | D38: закрыт | G38: robots.txt отвечает 403
A39: S102 | B39: Peterborough City Council | C39: живой | D39: не нужен | E39: HTML | F39: https://www.peterborough.gov.uk | G39: раздела событий нет (404)
A40: S103 | B40: Ely City Council | C40: закрыт | D40: закрыт | G40: cityofelycouncil.org.uk: robots.txt отвечает 403
...

Sheet Этап 6
A1: ID | B1: Источник | C1: Блок | D1: Состояние | E1: Решение | F1: Новых уникальных (будущие, в зоне) | G1: Примечание
A2: S001 | B2: Visit Cambridge — events | C2: HTML-источники P1 | D2: живой | E2: подключён | F2: 83 | G2: 7 разделов /event-categories/ (постранично) + страницы событий; раздел family-friendly → категория family
A3: S012 | B3: Cambridge Junction | C3: HTML-источники P1 | D3: живой | E3: подключён | F3: 239 | G3: HTML /whats-on/page/N + страницы событий («Event Information»: дата, время, цена); кэш страниц
A4: S026 | B4: Chariots of Fire | C4: HTML-источники P1 | D4: живой | E4: ежегодное | F4: — | G4: через recurring_events (R11)
A5: S028 | B5: Cambridge Half Marathon | C5: HTML-источники P1 | D5: живой | E5: ежегодное | F5: — | G5: через recurring_events (R03)
A6: S030 | B6: Cambridge Festival (университет) | C6: HTML-источники P1 | D6: живой | E6: ежегодное | F6: — | G6: Cambridge Festival — весна; дата через recurring_events (R04); коллектор программы — перед фестивалем (март)
A7: S031 | B7: Cambridge Folk Festival | C7: HTML-источники P1 | D7: живой | E7: ежегодное | F7: — | G7: через recurring_events (R09)
A8: S041 | B8: Cambridge Arts Theatre | C8: HTML-источники P1 | D8: закрыт | E8: покрыт | F8: — | G8: защита от ботов; афиша — через Ents24 (S006)
A9: S045 | B9: Arts Picturehouse | C9: HTML-источники P1 | D9: живой | E9: не нужен | F9: — | G9: сеансы — только через внутренний AJAX с XSRF-токеном сессии (не используем); обычные сеансы — не события выпуска; спецпоказы приходят через Visit Cambridge, статьи и Cambridge Film Festival (recurring R17)
A10: S048 | B10: University of Cambridge — What's On | C10: HTML-источники P1 | D10: живой | E10: подключён | F10: 41 | G10: недельные страницы admin.cam.ac.uk/whatson (3 недели) + раздел Families; iCal/RSS на webservices закрыты robots.txt — не используем
A11: S052 | B11: University of Cambridge Museums (сводный) | C11: HTML-источники P1 | D11: живой | E11: подключён | F11: 87 | G11: сводная афиша 8 музеев (HTML, один запрос на весь список) + 4 запроса по фильтрам «для кого»/«тип» → категория family по разметке музеев
A12: S056 | B12: Семейные программы музеев | C12: HTML-источники P1 | D12: — | E12: производный | F12: — | G12: тег «дети» из музейных источников — теперь по разметке S052/S048/S001 (категория family) и KIDS_RE
A13: S062 | B13: Комедия на Corn Exchange / Junction / ADC | C13: HTML-источники P1 | D13: — | E13: производный | F13: — | G13: тег «комедия» из S011, S012, S042
A14: S065 | B14: Open Cambridge | C14: HTML-источники P1 | D14: живой | E14: ежегодное | F14: — | G14: через recurring_events (R12)
A15: S069 | B15: Cambridge University Botanic Garden | C15: HTML-источники P1 | D15: живой | E15: подключён | F15: 17 | G15: HTML /whats-on/ + страницы событий; часть событий есть и в S052
A16: S070 | B16: National Trust: Wimpole, Anglesey Abbey, Wicken Fen | C16: HTML-источники P1 | D16: закрыт | E16: вручную | F16: — | G16: National Trust — защита Radware; ручной сезонный календарь
A17: S081 | B17: Thriplow Daffodil Weekend | C17: HTML-источники P1 | D17: живой | E17: ежегодное | F17: — | G17: через recurring_events (R02)
A18: S082 | B18: Cambridge Dragon Boat Festival (ACT) | C18: HTML-источники P1 | D18: живой | E18: ежегодное | F18: — | G18: через recurring_events (R10)
A19: S089 | B19: Town and Gown 10k | C19: HTML-источники P1 | D19: закрыт | E19: ежегодное | F19: — | G19: Cloudflare; через статьи и recurring_events (R14, вручную)
A20: S090 | B20: DesignMyNight — Cambridge | C20: HTML-источники P1 | D20: закрыт | E20: не собираем | F20: — | G20: robots.txt запрещает раздел событий
A21: S054 | B21: Cambridge Science Centre | C21: Семейные источники | D21: живой | E21: подключён | F21: 9 | G21: ссылки — из RSS /whats-on/feed/, дата и время — со страницы события; все события — семейные (family)
A22: S055 | B22: Библиотеки Cambridgeshire | C22: Семейные источники | D22: живой | E22: подключён | F22: 12 | G22: события библиотек — на Eventbrite (страница организатора со страницы совета), JSON-LD страниц событий; серии помечены «recurring series»
A23: S100 | B23: Huntingdonshire District Council | C23: Семейные источники | D23: закрыт | E23: закрыт | F23: — | G23: Hinchingbrooke Country Park: события только на TicketSource (robots.txt отвечает 403 — считаем запретом) и в Facebook (не парсим); страница совета без дат — проверить на этапе 6b через поиск
A24: S130 | B24: Museum of Cambridge | C24: Семейные источники | D24: живой | E24: подключён | F24: 7 | G24: Museum of Cambridge — REST The Events Calendar
A25: S131 | B25: Cambridge Past, Present & Future (Wandlebury, Leper Chapel, Hinxton Watermill…) | C25: Семейные источники | D25: живой | E25: подключён | F25: 106 | G25: Cambridge Past, Present & Future: Wandlebury, Leper Chapel, Hinxton Watermill, Coton, Bourn Windmill, Grantchester — список /events-list/ (Eventin), один запрос
A26: S134 | B26: Centre for Computing History | C26: Семейные источники | D26: живой | E26: подключён | F26: 6 | G26: Centre for Computing History — страница What's On, дата и название в ссылке
A27: S132 | B27: Milton Country Park | C27: Семейные места и аттракционы | D27: живой | E27: подключён | F27: 7 | G27: Milton Country Park (Wix): список /events — название, день, место
A28: S133 | B28: Nene Park / Ferry Meadows | C28: Семейные места и аттракционы | D28: закрыт | E28: отложен | F28: — | G28: Nene Park / Ferry Meadows: при проверке JSON-LD Event на /events/ (24 события), но при сборе сайт начал обрывать соединение и отвечать 403 — защита от ботов, не обходим; коллектор написан (family_misc.NenePark), из прогона убран — повторить позже / этап 6b
A29: S135 | B29: Shepreth Wildlife Park | C29: Семейные места и аттракционы | D29: закрыт | E29: закрыт | F29: — | G29: Shepreth Wildlife Park: сайт отвечает 403 / обрывает соединение — не обходим; этап 6b
A30: S136 | B30: Linton Zoo | C30: Семейные места и аттракционы | D30: живой | E30: не нужен | F30: — | G30: Linton Zoo: на сайте и в DigiTickets — только входные билеты, событий нет; сезонные события — через статьи
A31: S137 | B31: Hamerton Zoo Park | C31: Семейные места и аттракционы | D31: закрыт | E31: закрыт | F31: — | G31: Hamerton Zoo Park: 429 на robots.txt и главную — считаем запретом, повторить на этапе 6b
A32: S138 | B32: Wimpole Home Farm (National Trust) | C32: Семейные места и аттракционы | D32: закрыт | E32: вручную | F32: — | G32: Wimpole Home Farm — National Trust (S070): защита Radware, ручной сезонный календарь
A33: S139 | B33: Audley End House (English Heritage) | C33: Семейные места и аттракционы | D33: живой | E33: отложен | F33: — | G33: Audley End (English Heritage): события на странице загружаются скриптом, в HTML дат нет; JSON-LD нет — этап 6b (поиск) или ручной сезонный календарь
A34: S140 | B34: Woburn Safari Park | C34: Семейные места и аттракционы | D34: живой | E34: отложен | F34: — | G34: Woburn Safari Park: страница событий отвечает 500; вне графства, ~55 км — только события ≥ 7 по правилу 40–60 км
A35: S039 | B35: Рождественские маркеты в центре | C35: Поля, церкви, ярмарки | D35: живой | E35: ежегодное | F35: — | G35: Christmas in Cambridge (Parker's Piece: каток, маркет, колесо) — recurring R21, дата со страницы (13.11.2026 – 3.01.2027)
A36: S071 | B36: Ely Cathedral | C36: Поля, церкви, ярмарки | D36: живой | E36: подключён | F36: 29 | G36: Ely Cathedral: карточки /events (дата + название), один запрос; отложен в P2 на этапе 5
A37: S141 | B37: A Church Near You (Church of England) | C37: Поля, церкви, ярмарки | D37: живой | E37: не нужен | F37: — | G37: A Church Near You: robots.txt разрешает (кроме /christmas/events/), но события — по страницам каждого прихода (сотни в епархии Ely) и в основном регулярные службы; единого источника на графство нет. Концерты крупных церквей уже приходят через Ents24 (King's Chapel, Great St Mary's), University What's On (обеденные концерты GSM) и Visit Cambridge; пропуски — проверить на этапе 6b
A38: S142 | B38: ChurchSuite | C38: Поля, церкви, ярмарки | D38: закрыт | E38: закрыт | F38: — | G38: ChurchSuite: churchsuite.com за Cloudflare (403) — не обходим; календари отдельных приходов (<приход>.churchsuite.com) — если найдутся на этапе 6b
A39: S143 | B39: King's College Chapel | C39: Поля, церкви, ярмарки | D39: живой | E39: покрыт | F39: — | G39: King's College Chapel: страница концертов без дат в HTML; концерты есть в Ents24 (S006) и Visit Cambridge
A40: S144 | B40: St John's College Chapel | C40: Поля, церкви, ярмарки | D40: живой | E40: покрыт | F40: — | G40: St John's College Chapel: события — отдельными страницами без списка с датами; крупные концерты — в Visit Cambridge
...

Sheet Этап 6c
A1: ID | B1: Источник | C1: Состояние | D1: Решение | E1: Событий от источника | F1: Новых уникальных | G1: Новых в окне 1–11.10 | H1: Примечание | I1: Какое прежнее решение было ошибочным и почему
A2: S019 | B2: Cambridge City FC | C2: живой | D2: подключён | E2: 1 | F2: 1 | G2: 1 | H2: Cambridge City FC: домашние матчи из событий сайта клуба (Wix) → «Спорт → Также играют» | I2: S019 (этап 6: «не нужен, матчи низкой значимости») — отменено владельцем проекта после v5
A3: S020 | B3: Cambridge Rugby Club | C3: живой | D3: подключён | E3: 11 | F3: 11 | G3: 1 | H3: Cambridge RUFC: сайт клуба за бот-защитой; с 2026/27 — National League 1 (выбыли из Champ Rugby), весь сезон — PDF лиги (nationalleaguerugby.com) | I3: S020 (этап 5: «закрыт — бот-защита») — календарь нашёлся на сайте лиги
A4: S042 | B4: ADC Theatre | C4: живой | D4: подключён | E4: 28 | F4: 0 | G4: 0 | H4: ADC Theatre: цены — со страницы продажи adctheatre.com (robots.txt отвечает 404 — правил нет)
A5: S045 | B5: Arts Picturehouse | C5: живой | D5: подключён | E5: 5 | F5: 5 | G5: 5 | H5: Arts Picturehouse: страница кинотеатра без AJAX — спецпоказы с датой и «Now Playing»; сеансы (AJAX с XSRF-токеном) не используем | I5: S045 (этап 6: «не нужен») — ошибочно: для рубрики «В кино» нужны спецпоказы и новые фильмы, а не сеансы
