Workbook

Sheet Как пользоваться
A1: Реестр источников событий — Кембридж и окрестности (v0.4, сентябрь 2026)
A3: Источники — основная таблица. Одна строка = один источник. Фильтры в заголовке.
A4: Жёлтым выделено: URL не проверен или не указан — нужно найти/подтвердить перед написанием парсера.
A5: «URL проверен = да» — адрес подтверждён поиском; «проверить» — источник известен, но адрес и формат нужно сверить.
A6: Приоритет: 1 — брать в MVP, 2 — вторая волна, 3 — когда будет время.
A7: Способ сбора: RSS / iCal / API — дешёвый и надёжный; HTML — парсинг; Ручной — ежегодные события, проще завести руками.
A8: Сводка — счётчики по категориям (формулы, пересчитываются сами).
A9: Схема события — поля, которые парсер должен заполнять для каждого события.
A10: Категории и теги — справочник значений для полей category и тегов.
A12: Пример строки: S047 Talks.cam — готовые iCal/RSS/XML-фиды с датой, местом и организатором; приоритет 1.
A13: v0.4 (2026-09-27): проверены источники приоритета 1 — см. лист «Проверка P1»; новые столбцы «Endpoint для сбора», «robots.txt», «Проверено». «URL проверен = нет» — URL не отвечает (красный).

Sheet Источники
A1: ID | B1: Категория | C1: Источник | D1: Тип источника | E1: URL | F1: Что покрывает | G1: Зона | H1: Способ сбора | I1: Частота | J1: Приоритет | K1: URL проверен | L1: Заметки | M1: Endpoint для сбора | N1: robots.txt | O1: Проверено
A2: S001 | B2: Сквозные агрегаторы | C2: Visit Cambridge — events | D2: Агрегатор | E2: https://www.visitcambridge.org | F2: Официальный туристический календарь, все категории | G2: Центр | H2: API + HTML | I2: Ежедневно | J2: 1 | K2: да | L2: Хорошая опорная база, но туристический уклон. v0.4: внутренний API vc-map отдаёт события с адресом и postcode, но без дат — даты брать со страниц /event/… | M2: https://www.visitcambridge.org/wp-json/vc-map/v1/events | N2: разрешено | O2: 2026-09-27
A3: S002 | B3: Сквозные агрегаторы | C3: What's On In Cambridge | D3: Агрегатор | E3: https://www.whatsonincambridge.com/__superjs/challenge?u=%2Fevents%2F | F3: Календарь событий, все категории | G3: Центр | H3: RSS | I3: Ежедневно | J3: 1 | K3: да | L3: Сами предупреждают, что обновляют не каждый день — использовать как подсказку, сверять с первоисточником. v0.4: RSS жив (10 записей); страница /events/ за JS-проверкой | M3: https://www.whatsonincambridge.com/feed/ | N3: разрешено | O3: 2026-09-27
A4: S003 | B4: Сквозные агрегаторы | C4: Cambridge Independent — What's On | D4: СМИ | E4: https://www.cambridgeindependent.co.uk/whats-on/ | F4: Анонсы концертов, театра, кино, семейного | G4: Центр + 30 мин | H4: RSS | I4: Ежедневно | J4: 1 | K4: да | L4: Также спортивный раздел — календари United | M4: https://www.cambridgeindependent.co.uk/_api/rss/cambridge_independent_whatson_feed.xml | N4: разрешено | O4: 2026-09-27
A5: S004 | B5: Сквозные агрегаторы | C5: Cambridge News / CambridgeshireLive | D5: СМИ | E5: https://www.cambridge-news.co.uk | F5: Новости, анонсы, отмены, перекрытия | G5: Центр + час | H5: RSS | I5: 2–3 раза в день | J5: 1 | K5: да | L5: Ключевой источник для контура отмен. v0.4: раздел What's On: /whats-on/?service=rss; общий фид новостей /?service=rss — для контура отмен | M5: https://www.cambridge-news.co.uk/whats-on/?service=rss | N5: разрешено | O5: 2026-09-27
A6: S005 | B6: Сквозные агрегаторы | C6: Cambridge 105 — события | D6: СМИ / календарь | E6: https://cambridge105.co.uk | F6: Общественное радио, календарь местных событий | G6: Центр | H6: iCal | I6: Ежедневно | J6: 1 | K6: да | L6: Поймал Thriplow Daffodil Weekend — сильный источник по деревенскому long tail. v0.4: iCal The Events Calendar (22 события) + REST /wp-json/tribe/events/v1/events | M6: https://cambridge105.co.uk/whatson/?ical=1 | N6: разрешено | O6: 2026-09-27
A7: S006 | B7: Сквозные агрегаторы | C7: Ents24 — Cambridge | D7: Агрегатор | E7: https://www.ents24.com/whatson/cambridge | F7: Концерты, комедия, театр по всем площадкам | G7: Центр + 30 мин | H7: JSON-LD | I7: Ежедневно | J7: 1 | K7: да | L7: Удобно ловить объявления новых шоу | M7: https://www.ents24.com/whatson/cambridge | N7: разрешено | O7: 2026-09-27
A8: S007 | B8: Сквозные агрегаторы | C8: Skiddle — Cambridge | D8: Агрегатор / билеты | E8: https://www.skiddle.com/whats-on/Cambridge/ | F8: Клубы, гиги, фестивали | G8: Центр | H8: JSON-LD (API — по ключу) | I8: Ежедневно | J8: 1 | K8: да | L8: Есть API и партнёрка — сразу и данные, и монетизация. v0.4: страница отдаёт ~49 событий JSON-LD; официальный API требует партнёрский ключ (github.com/Skiddle/web-api) | M8: https://www.skiddle.com/whats-on/Cambridge/ | N8: разрешено | O8: 2026-09-27
A9: S008 | B9: Сквозные агрегаторы | C9: Eventbrite — Cambridge | D9: Агрегатор / билеты | E9: https://www.eventbrite.co.uk | F9: Воркшопы, лекции, нетворкинг, благотворительность | G9: Центр + 30 мин | H9: HTML (публичный поиск по API закрыт — проверить) | I9: Ежедневно | J9: 2 | K9: проверить | L9: Много шума — нужен жёсткий фильтр
A10: S009 | B10: Сквозные агрегаторы | C10: Songkick — площадки Кембриджа | D10: Агрегатор | E10: https://www.songkick.com | F10: Концерты по площадкам | G10: Центр | H10: HTML (API для новых партнёров ограничен — проверить) | I10: Еженедельно | J10: 3 | K10: да
A11: S010 | B11: Сквозные агрегаторы | C11: Peterborough Telegraph | D11: СМИ | E11: https://www.peterboroughtoday.co.uk | F11: Север графства: Уиттлси, Питерборо, фены | G11: Час | H11: RSS (уточнить) | I11: Ежедневно | J11: 2 | K11: да | L11: Закрывает дыру по Straw Bear и северу
A12: S011 | B12: Концерты | C12: Cambridge Corn Exchange | D12: Площадка | E12: https://www.cornex.co.uk/events | F12: Крупные концерты, комедия, балет, городские события | G12: Центр | H12: HTML + JSON-LD | I12: Ежедневно | J12: 1 | K12: да | L12: Сайт Cambridge Live — там же городские события (фейерверки и др.). v0.4: сайт Corn Exchange — cornex.co.uk; список в HTML, на странице события JSON-LD Event с адресом и postcode; cambridgelive.org.uk → билетный сайт | M12: https://www.cornex.co.uk/events | N12: разрешено | O12: 2026-09-27
A13: S012 | B13: Концерты | C13: Cambridge Junction | D13: Площадка | E13: https://www.junction.co.uk | F13: Концерты, комедия, клубные вечера, театр | G13: Центр | H13: API + HTML | I13: Ежедневно | J13: 1 | K13: да | L13: v0.4: WP REST, тип cj_events: названия и ссылки, дат нет — даты со страниц; /feed/ — это блог, не афиша | M13: https://www.junction.co.uk/wp-json/wp/v2/cj_events | N13: разрешено | O13: 2026-09-27
A14: S013 | B14: Концерты | C14: The Portland Arms | D14: Площадка | F14: Небольшие рок/инди-концерты | G14: Центр | H14: Через Ents24/Skiddle | I14: Еженедельно | J14: 2 | K14: проверить | L14: Собственный сайт найти
A15: S014 | B15: Концерты | C15: Storey's Field Centre (Eddington) | D15: Площадка | F15: Камерная музыка, фолк, джаз | G15: Центр | H15: HTML | I15: Еженедельно | J15: 2 | K15: проверить
A16: S015 | B16: Концерты | C16: West Road Concert Hall | D16: Площадка | F16: Классика, университетские оркестры | G16: Центр | H16: HTML | I16: Еженедельно | J16: 2 | K16: проверить
A17: S016 | B17: Концерты | C17: Хоровая музыка колледжей (King's, St John's, Trinity) | D17: Площадка | F17: Evensong, концерты хоров, органные вечера | G17: Центр | H17: HTML по колледжам | I17: Еженедельно | J17: 3 | K17: проверить | L17: Бесплатно — хороший материал для рубрики «бесплатно»
A18: S017 | B18: Концерты | C18: Saffron Hall | D18: Площадка | F18: Классика и крупные концерты | G18: Час | H18: HTML | I18: Еженедельно | J18: 2 | K18: проверить | L18: Saffron Walden
A19: S018 | B19: Спорт — смотреть | C19: Cambridge United | D19: Клуб | E19: https://www.cambridgeunited.com/fixture/list/57 | F19: Матчи Лиги 1, кубки | G19: Центр | H19: iCal (fixtur.es) + HTML | I19: Еженедельно | J19: 1 | K19: да | L19: Календарь сезона публикуется летом целиком. v0.4: у клуба календарь только в HTML (/fixture/list/57); готовый iCal домашних матчей — сторонний fixtur.es, сверять с сайтом клуба | M19: https://ics.fixtur.es/v2/home/cambridge-united-fc.ics | N19: разрешено | O19: 2026-09-27
A20: S019 | B20: Спорт — смотреть | C20: Cambridge City FC | D20: Клуб | F20: Нон-лиг футбол | G20: 30 мин | H20: HTML | I20: Еженедельно | J20: 3 | K20: проверить
A21: S020 | B21: Спорт — смотреть | C21: Cambridge Rugby Club | D21: Клуб | F21: Регби, National League | G21: Центр | H21: HTML | I21: Еженедельно | J21: 2 | K21: проверить
A22: S021 | B22: Спорт — смотреть | C22: Newmarket Racecourses | D22: Площадка | E22: https://www.thejockeyclub.co.uk/newmarket/events-tickets/ | F22: Скачки, летние концерты Newmarket Nights | G22: 30 мин | H22: JSON-LD | I22: Еженедельно | J22: 1 | K22: да | L22: Сайт Jockey Club | M22: https://www.thejockeyclub.co.uk/newmarket/events-tickets/ | N22: разрешено | O22: 2026-09-27
A23: S022 | B23: Спорт — смотреть | C23: Huntingdon Racecourse | D23: Площадка | F23: Скачки | G23: 30 мин | H23: HTML | I23: Еженедельно | J23: 3 | K23: проверить | L23: Сайт Jockey Club
A24: S023 | B24: Спорт — смотреть | C24: CUCBC — May Bumps / Lent Bumps | D24: Организатор | F24: Университетские гонки гребных лодок: Lent Bumps (февраль–март) и May Bumps (июнь) | G24: Центр | H24: HTML | I24: Сезонно | J24: 2 | K24: проверить
A25: S024 | B25: Спорт — смотреть | C25: Town Bumps (Cambridgeshire Rowing Association) | D25: Организатор | F25: Городские гонки гребных лодок, лето | G25: Центр | H25: HTML | I25: Сезонно | J25: 3 | K25: проверить
A26: S025 | B26: Спорт — смотреть | C26: Varsity-матчи (Oxford vs Cambridge) | D26: Организатор | F26: Регби, гребля и др. дерби университетов | G26: Центр + Лондон | H26: Ручной (календарь) | I26: Ежегодно | J26: 3 | K26: проверить
A27: S026 | B27: Спорт — участвовать | C27: Chariots of Fire | D27: Организатор | E27: https://www.chariots-of-fire.co.uk/ | F27: Благотворительная эстафета, сентябрь | G27: Центр | H27: JSON-LD (RunThrough) | I27: Ежегодно | J27: 1 | K27: да | L27: Регистрация через RunThrough. v0.4: ежегодно; JSON-LD Event на странице RunThrough; /feed/ сайта — новости | M27: https://www.runthrough.co.uk/event/chariots-of-fire-september-2026 | N27: разрешено | O27: 2026-09-27
A28: S027 | B28: Спорт — участвовать | C28: RunThrough — события в Кембридже | D28: Организатор / регистрация | E28: https://www.runthrough.co.uk | F28: Забеги, эстафеты | G28: Центр + 30 мин | H28: HTML | I28: Еженедельно | J28: 2 | K28: да
A29: S028 | B29: Спорт — участвовать | C29: Cambridge Half Marathon | D29: Организатор | E29: https://cambridgehalfmarathon.com/ | F29: Полумарафон, март | G29: Центр | H29: HTML | I29: Ежегодно | J29: 1 | K29: да | L29: Важен и для рубрики «Практическое» — перекрытия | M29: https://cambridgehalfmarathon.com/ | N29: разрешено | O29: 2026-09-27
A30: S029 | B30: Спорт — участвовать | C30: Let's Do This — Cambridgeshire | D30: Агрегатор / регистрация | E30: https://www.letsdothis.com | F30: Забеги, триатлоны, велозаезды | G30: Час | H30: HTML | I30: Еженедельно | J30: 2 | K30: да
A31: S030 | B31: Фестивали | C31: Cambridge Festival (университет) | D31: Организатор | E31: https://www.festival.cam.ac.uk/events | F31: Наука, гуманитарные темы, весна | G31: Центр | H31: HTML | I31: Сезонно | J31: 1 | K31: да | L31: v0.4: фестиваль в марте; часть событий дублируется в talks.cam | M31: https://www.festival.cam.ac.uk/events | N31: разрешено, Crawl-delay 10 | O31: 2026-09-27
A32: S031 | B32: Фестивали | C32: Cambridge Folk Festival | D32: Организатор | E32: https://www.cambridgefolkfestival.co.uk/ | F32: Фолк-фестиваль, лето | G32: Центр | H32: HTML | I32: Ежегодно | J32: 1 | K32: да | L32: v0.4: ежегодно; cambridgelive.org.uk/folk-festival → cambridgefolkfestival.co.uk | M32: https://www.cambridgefolkfestival.co.uk/ | N32: разрешено | O32: 2026-09-27
A33: S032 | B33: Фестивали | C33: Cambridge Beer Festival | D33: Организатор | E33: https://www.cambridgebeerfestival.com | F33: Пивной фестиваль CAMRA, май | G33: Центр | H33: iCal | I33: Ежегодно | J33: 1 | K33: да | M33: https://www.cambridgebeerfestival.com/events/?ical=1 | N33: разрешено | O33: 2026-09-27
A34: S033 | B34: Фестивали | C34: Strawberry Fair | D34: Организатор | E34: https://strawberry-fair.org.uk/ | F34: Бесплатный фестиваль на Midsummer Common, июнь | G34: Центр | H34: JSON-LD | I34: Ежегодно | J34: 1 | K34: да | L34: Бывали отмены — мониторить. v0.4: JSON-LD Event на главной; /feed/ отдаёт HTML, фида нет | M34: https://strawberry-fair.org.uk/ | N34: разрешено | O34: 2026-09-27
A35: S034 | B35: Фестивали | C35: Whittlesea Straw Bear Festival | D35: Организатор | F35: Средневековый зимний фестиваль, январь | G35: Час | H35: Ручной + Peterborough Telegraph | I35: Ежегодно | J35: 2 | K35: проверить
A36: S035 | B36: Фестивали | C36: Cambridge Film Festival | D36: Организатор | F36: Кинофестиваль, осень | G36: Центр | H36: Ручной (ежегодно) | I36: Ежегодно | J36: 2 | K36: проверить
A37: S036 | B37: Фестивали | C37: Cambridge Literary Festival | D37: Организатор | F37: Литфестиваль, весна и осень | G37: Центр | H37: HTML | I37: Сезонно | J37: 2 | K37: проверить
A38: S037 | B38: Фестивали | C38: Cambridge Science Festival / семейные программы | D38: Организатор | F38: См. Cambridge Festival | G38: Центр | H38: — | I38: — | J38: 3 | K38: проверить | L38: Дубль — проверить, не слит ли с Cambridge Festival
A39: S038 | B39: Ярмарки | C39: Mill Road Winter Fair | D39: Организатор | E39: https://www.millroadwinterfair.org | F39: Уличная ярмарка, первая суббота декабря; Mill Road Fringe в течение года | G39: Центр | H39: RSS | I39: Еженедельно в сезон | J39: 1 | K39: да | L39: Отмены публикуются в соцсетях — нужен контур отмен. v0.4: RSS — новости ярмарки; дату (5.12.2026) и отмены сверять по главной | M39: https://www.millroadwinterfair.org/feed/ | N39: разрешено | O39: 2026-09-27
A40: S039 | B40: Ярмарки | C40: Рождественские маркеты в центре | D40: Организатор | E40: https://www.christmasincambridge.co.uk/ | F40: Сезонные рынки | G40: Центр | H40: HTML | I40: Сезонно | J40: 1 | K40: да | L40: v0.4: сезонно (ноябрь–декабрь); фидов нет | M40: https://www.christmasincambridge.co.uk/ | N40: разрешено | O40: 2026-09-27
...

Sheet Проверка P1
A1: ID | B1: Источник | C1: URL проверен | D1: Способ сбора | E1: Endpoint | F1: Что нашёл | G1: Что не получилось
A2: S001 | B2: Visit Cambridge — events | C2: да | D2: API + HTML | E2: https://www.visitcambridge.org/wp-json/vc-map/v1/events | F2: https://www.visitcambridge.org — 200; alternate-фиды: https://www.visitcambridge.org/wp-json/wp/v2/pages/26, https://www.visitcambridge.org/wp-json/oembed/1.0/embed?url=https%3A%2F%2Fwww.visitcambridge.org%2F; WordPress https://www.visitcambridge.org/whats-on/ — 200; alternate-фиды: https://www.visitcambridge.org/wp-json/wp/v2/pages/553, https://www.visitcambridge.org/wp-json/oembed/1.0/embed?url=https%3A%2F%2Fwww.visitcambridge.org%2Fwhats-on%2F; WordPress https://www.visitcambridge.org/event-categories/festivals/ — 200; alternate-фиды: https://www.visitcambridge.org/event-categories/festivals/feed/; WordPress https://www.visitcambridge.org/wp-json/vc-map/v1/events — 200; JSON
A3: S002 | B3: What's On In Cambridge | C3: да | D3: RSS | E3: https://www.whatsonincambridge.com/feed/ | F3: https://www.whatsonincambridge.com/__superjs/challenge?u=%2Fevents%2F — 200 https://www.whatsonincambridge.com/feed/ — 200; фид, записей: 10 | G3: https://www.whatsonincambridge.com/events/ — JS-проверка «SuperJS» (бот-блок), HTML без браузера недоступен
A4: S003 | B4: Cambridge Independent — What's On | C4: да | D4: RSS | E4: https://www.cambridgeindependent.co.uk/_api/rss/cambridge_independent_whatson_feed.xml | F4: https://www.cambridgeindependent.co.uk/whats-on/ — 200 https://www.cambridgeindependent.co.uk/_api/rss/cambridge_independent_whatson_feed.xml — 200; фид, записей: 20
A5: S004 | B5: Cambridge News / CambridgeshireLive | C5: да | D5: RSS | E5: https://www.cambridge-news.co.uk/whats-on/?service=rss | F5: https://www.cambridge-news.co.uk — 200; alternate-фиды: https://www.cambridge-news.co.uk/rss.xml https://www.cambridge-news.co.uk/whats-on/ — 200; alternate-фиды: https://www.cambridge-news.co.uk/whats-on/rss.xml; билетная система: ecal https://www.cambridge-news.co.uk/?service=rss — 200; фид, записей: 25 https://www.cambridge-news.co.uk/whats-on/?service=rss — 200; фид, записей: 15 https://www.cambridge-news.co.uk/whats-on/?service=rss — 200; фид, записей: 15
A6: S005 | B6: Cambridge 105 — события | C6: да | D6: iCal | E6: https://cambridge105.co.uk/whatson/?ical=1 | F6: https://cambridge105.co.uk — 200; alternate-фиды: https://cambridge105.co.uk/whatson/?ical=1, https://cambridge105.co.uk/wp-json/wp/v2/pages/44141, https://cambridge105.co.uk/wp-json/oembed/1.0/embed?url=https%3A%2F%2Fcambridge105.co.uk%2F; WordPress https://cambridge105.co.uk/events/ — 200; alternate-фиды: https://cambridge105.co.uk/whatson/?ical=1, https://cambridge105.co.uk/wp-json/wp/v2/media/75261, https://cambridge105.co.uk/wp-json/oembed/1.0/embed?url=https%3A%2F%2Fcambridge105.co.uk%2Fevents%2F; WordPress https://cambridge105.co.uk/feed/ — 200; фид, записей: 30 https://cambridge105.co.uk/events/?ical=1 — 200; iCal, событий: 22 https://cambridge105.co.uk/wp-json/tribe/events/v1/events — 200; JSON https://cambridge105.co.uk/whatson/?ical=1 — 200; iCal, событий: 22
A7: S006 | B7: Ents24 — Cambridge | C7: да | D7: JSON-LD | E7: https://www.ents24.com/whatson/cambridge | F7: https://www.ents24.com/whatson/cambridge — 200; JSON-LD Event: 37; билетная система: ents24, gigantic
A8: S007 | B8: Skiddle — Cambridge | C8: да | D8: JSON-LD (API — по ключу) | E8: https://www.skiddle.com/whats-on/Cambridge/ | F8: https://www.skiddle.com/whats-on/Cambridge/ — 200; JSON-LD Event: 49; билетная система: ecal, skiddle https://www.skiddle.com/api/ — 200; билетная система: skiddle
A9: S011 | B9: Cambridge Corn Exchange | C9: да | D9: HTML + JSON-LD | E9: https://www.cornex.co.uk/events | F9: https://www.cambridgelivetickets.co.uk/ — 200 https://www.cornex.co.uk — 200 https://www.cornex.co.uk/events — 200 https://www.cambridgelivetickets.co.uk — 200 https://www.cornex.co.uk/events/alison-moyet-2 — 200; JSON-LD Event: 1
A10: S012 | B10: Cambridge Junction | C10: да | D10: API + HTML | E10: https://www.junction.co.uk/wp-json/wp/v2/cj_events | F10: https://www.junction.co.uk — 200; alternate-фиды: https://www.junction.co.uk/feed/, https://www.junction.co.uk/comments/feed/, https://www.junction.co.uk/wp-json/oembed/1.0/embed?url=https%3A%2F%2Fwww.junction.co.uk%2F; WordPress; билетная система: ecal, spektrix https://www.junction.co.uk/whats-on/ — 200; alternate-фиды: https://www.junction.co.uk/feed/, https://www.junction.co.uk/comments/feed/, https://www.junction.co.uk/wp-json/oembed/1.0/embed?url=https%3A%2F%2Fwww.junction.co.uk%2Fwhats-on%2F; WordPress; билетная система: ecal, spektrix https://www.junction.co.uk/wp-json/wp/v2/cj_events?per_page=20 — 200; JSON https://www.junction.co.uk/feed/ — 200; фид, записей: 12
A11: S018 | B11: Cambridge United | C11: да | D11: iCal (fixtur.es) + HTML | E11: https://ics.fixtur.es/v2/home/cambridge-united-fc.ics | F11: https://www.cambridgeunited.com — 200 https://fixtur.es/en/team/cambridge-united-fc/home — 200; JSON-LD Event: 27 https://www.cambridgeunited.com/fixture/list/57 — 200 https://ics.fixtur.es/v2/home/cambridge-united-fc.ics — 200; iCal, событий: 188
A12: S021 | B12: Newmarket Racecourses | C12: да | D12: JSON-LD | E12: https://www.thejockeyclub.co.uk/newmarket/events-tickets/ | F12: https://www.thejockeyclub.co.uk/newmarket/ — 200 https://www.thejockeyclub.co.uk/newmarket/events-tickets/ — 200; JSON-LD Event: 14
A13: S026 | B13: Chariots of Fire | C13: да | D13: JSON-LD (RunThrough) | E13: https://www.runthrough.co.uk/event/chariots-of-fire-september-2026 | F13: https://www.chariots-of-fire.co.uk/ — 200; alternate-фиды: https://www.chariots-of-fire.co.uk/feed/, https://www.chariots-of-fire.co.uk/comments/feed/, https://www.chariots-of-fire.co.uk/wp-json/wp/v2/pages/21; WordPress https://www.chariots-of-fire.co.uk/feed/ — 200; фид, записей: 10 https://www.runthrough.co.uk/event/chariots-of-fire-september-2026 — 200; JSON-LD Event: 1
A14: S028 | B14: Cambridge Half Marathon | C14: да | D14: HTML | E14: https://cambridgehalfmarathon.com/ | F14: https://cambridgehalfmarathon.com/ — 200
A15: S030 | B15: Cambridge Festival (университет) | C15: да | D15: HTML | E15: https://www.festival.cam.ac.uk/events | F15: https://www.festival.cam.ac.uk/events — 200 через curl, robots.txt разрешает (Crawl-delay: 10); фидов и JSON-LD нет | G15: Pantheon отдаёт 403 Python-клиенту httpx (и на robots.txt), curl с тем же User-Agent — 200: блок по отпечатку клиента
A16: S031 | B16: Cambridge Folk Festival | C16: да | D16: HTML | E16: https://www.cambridgefolkfestival.co.uk/ | F16: https://www.cambridgefolkfestival.co.uk/ — 200 https://www.cambridgefolkfestival.co.uk/ — 200
A17: S032 | B17: Cambridge Beer Festival | C17: да | D17: iCal | E17: https://www.cambridgebeerfestival.com/events/?ical=1 | F17: https://www.cambridgebeerfestival.com — 200; JSON-LD Event: 2; alternate-фиды: https://www.cambridgebeerfestival.com/events/?ical=1; WordPress + The Events Calendar; билетная система: ecal
A18: S033 | B18: Strawberry Fair | C18: да | D18: JSON-LD | E18: https://strawberry-fair.org.uk/ | F18: https://strawberry-fair.org.uk/ — 200; JSON-LD Event: 1 https://strawberry-fair.org.uk/feed/ — 200; JSON-LD Event: 1
A19: S038 | B19: Mill Road Winter Fair | C19: да | D19: RSS | E19: https://www.millroadwinterfair.org/feed/ | F19: https://www.millroadwinterfair.org — 200; alternate-фиды: https://www.millroadwinterfair.org/feed/, https://www.millroadwinterfair.org/comments/feed/, https://www.millroadwinterfair.org/wp-json/wp/v2/pages/22; WordPress https://www.millroadwinterfair.org/feed/ — 200; фид, записей: 0
A20: S039 | B20: Рождественские маркеты в центре | C20: да | D20: HTML | E20: https://www.christmasincambridge.co.uk/ | F20: https://www.christmasincambridge.co.uk/ — 200 https://www.visitcambridge.org/event/christmas-in-cambridge/ — 200; alternate-фиды: https://www.visitcambridge.org/wp-json/oembed/1.0/embed?url=https%3A%2F%2Fwww.visitcambridge.org%2Fevent%2Fchristmas-in-cambridge%2F; WordPress
A21: S041 | B21: Cambridge Arts Theatre | C21: проверить | D21: HTML (блок Cloudflare) | G21: https://www.artstheatre.co.uk — 403, Cloudflare challenge (cf-mitigated) и для httpx, и для curl
A22: S042 | B22: ADC Theatre | C22: да | D22: iCal | E22: https://www.camdram.net/venues/adc-theatre/diary.ics | F22: https://www.adctheatre.com — 200; билетная система: spektrix https://www.adctheatre.com/whats-on/ — 200; билетная система: spektrix https://www.camdram.net/venues/adc-theatre/diary.ics — 200; iCal, событий: 28 https://www.camdram.net/venues/adc-theatre/diary.json — 200; JSON
A23: S045 | B23: Arts Picturehouse | C23: да | D23: HTML | E23: https://www.picturehouses.com/cinema/arts-picturehouse-cambridge | F23: https://www.picturehouses.com/cinema/arts-picturehouse-cambridge — 200; билетная система: ecal
A24: S047 | B24: Talks.cam | C24: да | D24: iCal | E24: https://talks.cam.ac.uk/show/ics/5606/ | F24: https://talks.cam.ac.uk — 200 https://talks.cam.ac.uk/document/documentation/ — 200 https://talks.cam.ac.uk/show/ics/5606/ — 200; iCal, событий: 15 https://talks.cam.ac.uk/show/rss/5606/ — 200; фид, записей: 15 https://talks.cam.ac.uk/show/xml/5606/ — 200
A25: S048 | B25: University of Cambridge — What's On | C25: да | D25: HTML | E25: https://www.admin.cam.ac.uk/whatson/ | F25: https://www.admin.cam.ac.uk/whatson/ — 200 | G25: webservices.admin.cam.ac.uk (iCal 76 событий, RSS) — robots.txt: Disallow: / — не собираем без решения https://www.cam.ac.uk/whats-on — Pantheon 403 для httpx
A26: S050 | B26: Fitzwilliam Museum | C26: да | D26: RSS (выставки) + HTML (события) | E26: https://fitzmuseum.cam.ac.uk/feeds/exhibitions | F26: https://fitzmuseum.cam.ac.uk — 200; alternate-фиды: https://fitzmuseum.cam.ac.uk/feeds/news, https://fitzmuseum.cam.ac.uk/feeds/vacancies, https://fitzmuseum.cam.ac.uk/feeds/exhibitions https://fitzmuseum.cam.ac.uk/events — 200; alternate-фиды: https://fitzmuseum.cam.ac.uk/feeds/news, https://fitzmuseum.cam.ac.uk/feeds/vacancies, https://fitzmuseum.cam.ac.uk/feeds/exhibitions https://fitzmuseum.cam.ac.uk/feeds/exhibitions — 200; фид, записей: 20
A27: S051 | B27: Kettle's Yard | C27: да | D27: HTML | E27: https://www.kettlesyard.cam.ac.uk/whats-on/ | F27: https://www.kettlesyard.cam.ac.uk — 200 https://www.kettlesyard.cam.ac.uk/whats-on/ — 200 | G27: https://www.kettlesyard.cam.ac.uk/feed/ — 500 https://www.kettlesyard.co.uk — ConnectError: [SSL: CERTIFICATE_VERIFY_FAILED] certificate verify failed: Hostname mismatch, certificate is not valid for 'www.kettlesyard.co.uk'. (_ssl.c:1016) https://www.kettlesyard.co.uk/events/ — ConnectError: [SSL: CERTIFICATE_VERIFY_FAILED] certificate verify failed: Hostname mismatch, certificate is not valid for 'www.kettlesyard.co.uk'. (_ssl.c:1016) https://www.kettlesyard.co.uk/feed/ — ConnectError: [SSL: CERTIFICATE_VERIFY_FAILED] certificate verify failed: Hostname mismatch, certificate is not valid for 'www.kettlesyard.co.uk'. (_ssl.c:1016)
A28: S052 | B28: University of Cambridge Museums (сводный) | C28: да | D28: HTML | E28: https://www.museums.cam.ac.uk/whats-on | F28: https://www.museums.cam.ac.uk — 200 https://www.museums.cam.ac.uk/whats-on — 200
A29: S056 | B29: Семейные программы музеев | C29: проверить | D29: Производный (тег «дети») | G29: своего URL нет по замыслу
A30: S062 | B30: Комедия на Corn Exchange / Junction / ADC | C30: проверить | D30: Производный (тег «комедия») | G30: своего URL нет по замыслу
A31: S065 | B31: Open Cambridge | C31: да | D31: HTML | E31: https://www.opencambridge.cam.ac.uk/ | F31: https://www.opencambridge.cam.ac.uk/ — 200 через curl; фидов нет | G31: Pantheon отдаёт 403 Python-клиенту httpx, curl — 200
A32: S069 | B32: Cambridge University Botanic Garden | C32: да | D32: HTML | E32: https://www.botanic.cam.ac.uk/whats-on/ | F32: https://www.botanic.cam.ac.uk — 200; alternate-фиды: https://www.botanic.cam.ac.uk/wp-json/oembed/1.0/embed?url=https%3A%2F%2Fwww.botanic.cam.ac.uk%2F, https://www.botanic.cam.ac.uk/wp-json/wp/v2/pages/6; WordPress https://www.botanic.cam.ac.uk/whats-on/ — 200; WordPress
A33: S070 | B33: National Trust: Wimpole, Anglesey Abbey, Wicken Fen | C33: проверить | D33: HTML | E33: https://www.nationaltrust.org.uk/visit/cambridgeshire/wimpole-estate/events | F33: https://www.nationaltrust.org.uk/visit/cambridgeshire/wimpole-estate/events — 200 https://www.nationaltrust.org.uk/visit/cambridgeshire/anglesey-abbey-gardens-and-lode-mill/events — 200 https://www.nationaltrust.org.uk/visit/cambridgeshire/wicken-fen-nature-reserve/events — 200 | G33: nationaltrust.org.uk — после 1–2 запросов отдаёт страницу бот-защиты Radware Wicken Fen: /wicken-fen-nature-reserve/events — страница 404; верный адрес не подтверждён
A34: S072 | B34: Cambridge City Council — городские события | C34: да | D34: HTML | E34: https://www.camcityevents.co.uk/events | F34: https://www.cambridge.gov.uk — 200 https://www.cambridge.gov.uk/summer-events — 200 https://www.camcityevents.co.uk/events — 200 | G34: https://www.cambridge.gov.uk/fireworks — 404
A35: S081 | B35: Thriplow Daffodil Weekend | C35: да | D35: HTML | E35: https://www.thriplowdaffodils.org.uk | F35: https://www.thriplowdaffodils.org.uk — 200
A36: S082 | B36: Cambridge Dragon Boat Festival (ACT) | C36: да | D36: HTML | E36: https://act4addenbrookes.org.uk/dragonboat/ | F36: https://act4addenbrookes.org.uk — 200; alternate-фиды: https://act4addenbrookes.org.uk/feed/, https://act4addenbrookes.org.uk/comments/feed/, https://act4addenbrookes.org.uk/wp-json/oembed/1.0/embed?url=https%3A%2F%2Fact4addenbrookes.org.uk%2F; WordPress https://act4addenbrookes.org.uk/events/cambridge-dragon-boat-festival-2026/ — 200; alternate-фиды: https://act4addenbrookes.org.uk/feed/, https://act4addenbrookes.org.uk/comments/feed/, https://act4addenbrookes.org.uk/wp-json/oembed/1.0/embed?url=https%3A%2F%2Fact4addenbrookes.org.uk%2Fevents%2Fcambridge-dragon-boat-festival-2026%2F; WordPress
A37: S087 | B37: The Cambridge Foodies | C37: да | D37: RSS | E37: https://cambridgefoodies.me.uk/feed/ | F37: https://cambridgefoodies.me.uk — 200 в первом проходе, WordPress, alternate RSS /feed/ https://cambridgefoodies.me.uk/feed/ — 200 через HTTP/2 | G37: WordPress.com отвечает 429 при повторных запросах (и HTTP/1.1-клиенту httpx) — нужны HTTP/2, редкие запросы и бэк-офф
A38: S089 | B38: Town and Gown 10k | C38: проверить | D38: Ручной (сайт закрыт для ботов) | G38: townandgown10k.com и musculardystrophyuk.org — Cloudflare 403 для любого бот-клиента, включая robots.txt

Sheet Сводка
A1: Категория | B1: Всего источников | C1: Приоритет 1 | D1: URL проверен | E1: Осталось проверить
A2: Сквозные агрегаторы | B2: =COUNTIF(Источники!$B$2:$B$90,A2) | C2: =COUNTIFS(Источники!$B$2:$B$90,A2,Источники!$J$2:$J$90,1) | D2: =COUNTIFS(Источники!$B$2:$B$90,A2,Источники!$K$2:$K$90,"да") | E2: =B2-D2
A3: Концерты | B3: =COUNTIF(Источники!$B$2:$B$90,A3) | C3: =COUNTIFS(Источники!$B$2:$B$90,A3,Источники!$J$2:$J$90,1) | D3: =COUNTIFS(Источники!$B$2:$B$90,A3,Источники!$K$2:$K$90,"да") | E3: =B3-D3
A4: Спорт — смотреть | B4: =COUNTIF(Источники!$B$2:$B$90,A4) | C4: =COUNTIFS(Источники!$B$2:$B$90,A4,Источники!$J$2:$J$90,1) | D4: =COUNTIFS(Источники!$B$2:$B$90,A4,Источники!$K$2:$K$90,"да") | E4: =B4-D4
A5: Спорт — участвовать | B5: =COUNTIF(Источники!$B$2:$B$90,A5) | C5: =COUNTIFS(Источники!$B$2:$B$90,A5,Источники!$J$2:$J$90,1) | D5: =COUNTIFS(Источники!$B$2:$B$90,A5,Источники!$K$2:$K$90,"да") | E5: =B5-D5
A6: Фестивали | B6: =COUNTIF(Источники!$B$2:$B$90,A6) | C6: =COUNTIFS(Источники!$B$2:$B$90,A6,Источники!$J$2:$J$90,1) | D6: =COUNTIFS(Источники!$B$2:$B$90,A6,Источники!$K$2:$K$90,"да") | E6: =B6-D6
A7: Ярмарки | B7: =COUNTIF(Источники!$B$2:$B$90,A7) | C7: =COUNTIFS(Источники!$B$2:$B$90,A7,Источники!$J$2:$J$90,1) | D7: =COUNTIFS(Источники!$B$2:$B$90,A7,Источники!$K$2:$K$90,"да") | E7: =B7-D7
A8: Театр | B8: =COUNTIF(Источники!$B$2:$B$90,A8) | C8: =COUNTIFS(Источники!$B$2:$B$90,A8,Источники!$J$2:$J$90,1) | D8: =COUNTIFS(Источники!$B$2:$B$90,A8,Источники!$K$2:$K$90,"да") | E8: =B8-D8
A9: Кино | B9: =COUNTIF(Источники!$B$2:$B$90,A9) | C9: =COUNTIFS(Источники!$B$2:$B$90,A9,Источники!$J$2:$J$90,1) | D9: =COUNTIFS(Источники!$B$2:$B$90,A9,Источники!$K$2:$K$90,"да") | E9: =B9-D9
A10: Лекции | B10: =COUNTIF(Источники!$B$2:$B$90,A10) | C10: =COUNTIFS(Источники!$B$2:$B$90,A10,Источники!$J$2:$J$90,1) | D10: =COUNTIFS(Источники!$B$2:$B$90,A10,Источники!$K$2:$K$90,"да") | E10: =B10-D10
A11: Выставки и музеи | B11: =COUNTIF(Источники!$B$2:$B$90,A11) | C11: =COUNTIFS(Источники!$B$2:$B$90,A11,Источники!$J$2:$J$90,1) | D11: =COUNTIFS(Источники!$B$2:$B$90,A11,Источники!$K$2:$K$90,"да") | E11: =B11-D11
A12: Детям и семьям | B12: =COUNTIF(Источники!$B$2:$B$90,A12) | C12: =COUNTIFS(Источники!$B$2:$B$90,A12,Источники!$J$2:$J$90,1) | D12: =COUNTIFS(Источники!$B$2:$B$90,A12,Источники!$K$2:$K$90,"да") | E12: =B12-D12
A13: Еда и напитки | B13: =COUNTIF(Источники!$B$2:$B$90,A13) | C13: =COUNTIFS(Источники!$B$2:$B$90,A13,Источники!$J$2:$J$90,1) | D13: =COUNTIFS(Источники!$B$2:$B$90,A13,Источники!$K$2:$K$90,"да") | E13: =B13-D13
... A22: Практическое | B22: =COUNTIF(Источники!$B$2:$B$90,A22) | C22: =COUNTIFS(Источники!$B$2:$B$90,A22,Источники!$J$2:$J$90,1) | D22: =COUNTIFS(Источники!$B$2:$B$90,A22,Источники!$K$2:$K$90,"да") | E22: =B22-D22
A23: Итого | B23: =SUM(B2:B22) | C23: =SUM(C2:C22) | D23: =SUM(D2:D22) | E23: =SUM(E2:E22)

Sheet Схема события
A1: Поле | B1: Тип | C1: Обязательное | D1: Пример | E1: Комментарий
A2: event_id | B2: текст | C2: да | D2: EV-2026-000123 | E2: Внутренний ID
A3: title | B3: текст | C3: да | D3: Cambridge United vs AFC Wimbledon
A4: category | B4: список | C4: да | D4: Спорт — смотреть | E4: Из листа «Категории и теги»
A5: date_start | B5: дата | C5: да | D5: 2026-09-26
A6: time_start | B6: время | C6: да, если известно | D6: 15:00 | E6: Пусто = весь день
A7: date_end | B7: дата | C7: нет | D7: 2026-09-26 | E7: Для многодневных
A8: time_end | B8: время | C8: нет | D8: 17:00
A9: venue_name | B9: текст | C9: да | D9: Abbey Stadium
A10: address | B10: текст | C10: да | D10: Newmarket Road, Cambridge | E10: Точный адрес
A11: postcode | B11: текст | C11: да | D11: (заполнять из источника) | E11: Для карты и расчёта зоны
A12: lat / lon | B12: число | C12: нет | D12: 52.21, 0.15 | E12: Геокодирование по postcode
A13: zone | B13: список | C13: да | D13: Центр | E13: Тег: Центр / до 30 мин / до часа — считается автоматически
A14: price_from | B14: число, £ | C14: нет | D14: 0 | E14: 0 = бесплатно
A15: price_tag | B15: список | C15: да | D15: бесплатно / до £10 / дороже
A16: audience | B16: список (несколько) | C16: нет | D16: дети 5–12; семьи
A17: booking | B17: список | C17: да | D17: без билетов / бронировать / продажа скоро
A18: status | B18: список | C18: да | D18: по плану | E18: по плану / перенесено / отменено / sold out
A19: ticket_url | B19: URL | C19: нет | E19: Здесь партнёрская ссылка, если есть
A20: source_id | B20: ссылка | C20: да | D20: S018 | E20: ID из листа «Источники»
A21: source_url | B21: URL | C21: да | E21: Страница события у первоисточника
A22: description_short | B22: текст | C22: да | E22: 2–3 предложения своими словами (не копировать)
A23: score | B23: число 1–10 | C23: нет | D23: 8 | E23: Оценка LLM «стоит ли внимания»
A24: last_checked | B24: дата-время | C24: да | E24: Когда контур отмен последний раз проверял

Sheet Категории и теги
A1: Ось | B1: Значение
A2: Категория | B2: Концерты
A3: Категория | B3: Спорт — смотреть
A4: Категория | B4: Спорт — участвовать
A5: Категория | B5: Фестивали
A6: Категория | B6: Ярмарки
A7: Категория | B7: Театр
A8: Категория | B8: Кино
A9: Категория | B9: Лекции
A10: Категория | B10: Выставки и музеи
A11: Категория | B11: Детям и семьям
A12: Категория | B12: Еда и напитки
... A39: Статус | B39: sold out
